[2025-04-19T12:02:37.170+0000] {local_task_job_runner.py:123} INFO - ::group::Pre task execution logs
[2025-04-19T12:02:37.438+0000] {taskinstance.py:2614} INFO - Dependencies all met for dep_context=non-requeueable deps ti=<TaskInstance: dbt_etl_pipeline_staging.dbt_staging manual__2025-04-18T00:47:21.649681+00:00 [queued]>
[2025-04-19T12:02:37.484+0000] {taskinstance.py:2614} INFO - Dependencies all met for dep_context=requeueable deps ti=<TaskInstance: dbt_etl_pipeline_staging.dbt_staging manual__2025-04-18T00:47:21.649681+00:00 [queued]>
[2025-04-19T12:02:37.487+0000] {taskinstance.py:2867} INFO - Starting attempt 2 of 2
[2025-04-19T12:02:37.555+0000] {taskinstance.py:2890} INFO - Executing <Task(BashOperator): dbt_staging> on 2025-04-18 00:47:21.649681+00:00
[2025-04-19T12:02:37.595+0000] {logging_mixin.py:190} WARNING - /home/airflow/.local/lib/python3.12/site-packages/airflow/task/task_runner/standard_task_runner.py:70 DeprecationWarning: This process (pid=408) is multi-threaded, use of fork() may lead to deadlocks in the child.
[2025-04-19T12:02:37.593+0000] {standard_task_runner.py:104} INFO - Running: ['airflow', 'tasks', 'run', 'dbt_etl_pipeline_staging', 'dbt_staging', 'manual__2025-04-18T00:47:21.649681+00:00', '--job-id', '159', '--raw', '--subdir', 'DAGS_FOLDER/dbt_staging.py', '--cfg-path', '/tmp/tmpc5648ojk']
[2025-04-19T12:02:37.608+0000] {standard_task_runner.py:72} INFO - Started process 433 to run task
[2025-04-19T12:02:37.611+0000] {standard_task_runner.py:105} INFO - Job 159: Subtask dbt_staging
[2025-04-19T12:02:38.361+0000] {task_command.py:467} INFO - Running <TaskInstance: dbt_etl_pipeline_staging.dbt_staging manual__2025-04-18T00:47:21.649681+00:00 [running]> on host 8310323359f9
[2025-04-19T12:02:39.336+0000] {taskinstance.py:3134} INFO - Exporting env vars: AIRFLOW_CTX_DAG_OWNER='azizjon' AIRFLOW_CTX_DAG_ID='dbt_etl_pipeline_staging' AIRFLOW_CTX_TASK_ID='dbt_staging' AIRFLOW_CTX_EXECUTION_DATE='2025-04-18T00:47:21.649681+00:00' AIRFLOW_CTX_TRY_NUMBER='2' AIRFLOW_CTX_DAG_RUN_ID='manual__2025-04-18T00:47:21.649681+00:00'
[2025-04-19T12:02:39.339+0000] {taskinstance.py:732} INFO - ::endgroup::
[2025-04-19T12:02:39.414+0000] {subprocess.py:78} INFO - Tmp dir root location: /tmp
[2025-04-19T12:02:39.424+0000] {subprocess.py:88} INFO - Running command: ['/usr/bin/bash', '-c', '\n        export PATH=/home/airflow/.local/bin:$PATH\n        cd /opt/airflow/commerce_dbt\n        dbt run --select staging --profiles-dir .\n        ']
[2025-04-19T12:02:39.474+0000] {subprocess.py:99} INFO - Output:
[2025-04-19T12:02:49.681+0000] {subprocess.py:106} INFO - [0m12:02:49  Running with dbt=1.7.0
[2025-04-19T12:02:50.650+0000] {subprocess.py:106} INFO - [0m12:02:50  Registered adapter: postgres=1.7.0
[2025-04-19T12:02:51.893+0000] {subprocess.py:106} INFO - [0m12:02:51  [[33mWARNING[0m]: Configuration paths exist in your dbt_project.yml file which do not apply to any resources.
[2025-04-19T12:02:51.895+0000] {subprocess.py:106} INFO - There are 1 unused configuration paths:
[2025-04-19T12:02:51.896+0000] {subprocess.py:106} INFO - - seeds.initial_dataset
[2025-04-19T12:02:52.087+0000] {subprocess.py:106} INFO - [0m12:02:52  Found 13 models, 1 snapshot, 6 seeds, 43 tests, 6 sources, 0 exposures, 0 metrics, 401 macros, 0 groups, 0 semantic models
[2025-04-19T12:02:52.098+0000] {subprocess.py:106} INFO - [0m12:02:52
[2025-04-19T12:02:53.723+0000] {subprocess.py:106} INFO - [0m12:02:53  Concurrency: 4 threads (target='dev')
[2025-04-19T12:02:53.725+0000] {subprocess.py:106} INFO - [0m12:02:53
[2025-04-19T12:02:53.772+0000] {subprocess.py:106} INFO - [0m12:02:53  1 of 6 START sql table model commerce_staging.stg_customers .................... [RUN]
[2025-04-19T12:02:53.775+0000] {subprocess.py:106} INFO - [0m12:02:53  2 of 6 START sql table model commerce_staging.stg_order_items .................. [RUN]
[2025-04-19T12:02:53.780+0000] {subprocess.py:106} INFO - [0m12:02:53  3 of 6 START sql table model commerce_staging.stg_orders ....................... [RUN]
[2025-04-19T12:02:53.783+0000] {subprocess.py:106} INFO - [0m12:02:53  4 of 6 START sql table model commerce_staging.stg_product_categories ........... [RUN]
[2025-04-19T12:02:56.212+0000] {subprocess.py:106} INFO - [0m12:02:56  4 of 6 OK created sql table model commerce_staging.stg_product_categories ...... [[32mSELECT 4[0m in 2.39s]
[2025-04-19T12:02:56.215+0000] {subprocess.py:106} INFO - [0m12:02:56  1 of 6 OK created sql table model commerce_staging.stg_customers ............... [[32mSELECT 1000[0m in 2.42s]
[2025-04-19T12:02:56.298+0000] {subprocess.py:106} INFO - [0m12:02:56  5 of 6 START sql table model commerce_staging.stg_products ..................... [RUN]
[2025-04-19T12:02:56.319+0000] {subprocess.py:106} INFO - [0m12:02:56  3 of 6 OK created sql table model commerce_staging.stg_orders .................. [[32mSELECT 7000[0m in 2.50s]
[2025-04-19T12:02:56.330+0000] {subprocess.py:106} INFO - [0m12:02:56  6 of 6 START sql table model commerce_staging.stg_stores ....................... [RUN]
[2025-04-19T12:02:56.420+0000] {subprocess.py:106} INFO - [0m12:02:56  2 of 6 OK created sql table model commerce_staging.stg_order_items ............. [[32mSELECT 10000[0m in 2.52s]
[2025-04-19T12:02:57.133+0000] {subprocess.py:106} INFO - [0m12:02:57  5 of 6 OK created sql table model commerce_staging.stg_products ................ [[32mSELECT 17[0m in 0.83s]
[2025-04-19T12:02:57.292+0000] {subprocess.py:106} INFO - [0m12:02:57  6 of 6 ERROR creating sql table model commerce_staging.stg_stores .............. [[31mERROR[0m in 0.95s]
[2025-04-19T12:02:57.752+0000] {subprocess.py:106} INFO - [0m12:02:57
[2025-04-19T12:02:57.755+0000] {subprocess.py:106} INFO - [0m12:02:57  Finished running 6 table models in 0 hours 0 minutes and 5.65 seconds (5.65s).
[2025-04-19T12:02:57.898+0000] {subprocess.py:106} INFO - [0m12:02:57
[2025-04-19T12:02:57.901+0000] {subprocess.py:106} INFO - [0m12:02:57  [31mCompleted with 1 error and 0 warnings:[0m
[2025-04-19T12:02:57.913+0000] {subprocess.py:106} INFO - [0m12:02:57
[2025-04-19T12:02:57.915+0000] {subprocess.py:106} INFO - [0m12:02:57    Database Error in model stg_stores (models/staging/stg_stores.sql)
[2025-04-19T12:02:57.916+0000] {subprocess.py:106} INFO -   relation "stg_stores" already exists
[2025-04-19T12:02:57.917+0000] {subprocess.py:106} INFO -   compiled Code at target/run/commerce_dbt/models/staging/stg_stores.sql
[2025-04-19T12:02:57.920+0000] {subprocess.py:106} INFO - [0m12:02:57
[2025-04-19T12:02:57.924+0000] {subprocess.py:106} INFO - [0m12:02:57  Done. PASS=5 WARN=0 ERROR=1 SKIP=0 TOTAL=6
[2025-04-19T12:03:00.867+0000] {subprocess.py:110} INFO - Command exited with return code 1
[2025-04-19T12:03:01.316+0000] {taskinstance.py:3313} ERROR - Task failed with exception
Traceback (most recent call last):
  File "/home/airflow/.local/lib/python3.12/site-packages/airflow/models/taskinstance.py", line 768, in _execute_task
    result = _execute_callable(context=context, **execute_callable_kwargs)
             ^^^^^^^^^^^^^^^^^^^^^^^^^^^^^^^^^^^^^^^^^^^^^^^^^^^^^^^^^^^^^
  File "/home/airflow/.local/lib/python3.12/site-packages/airflow/models/taskinstance.py", line 734, in _execute_callable
    return ExecutionCallableRunner(
           ^^^^^^^^^^^^^^^^^^^^^^^^
  File "/home/airflow/.local/lib/python3.12/site-packages/airflow/utils/operator_helpers.py", line 252, in run
    return self.func(*args, **kwargs)
           ^^^^^^^^^^^^^^^^^^^^^^^^^^
  File "/home/airflow/.local/lib/python3.12/site-packages/airflow/models/baseoperator.py", line 424, in wrapper
    return func(self, *args, **kwargs)
           ^^^^^^^^^^^^^^^^^^^^^^^^^^^
  File "/home/airflow/.local/lib/python3.12/site-packages/airflow/operators/bash.py", line 276, in execute
    raise AirflowException(
airflow.exceptions.AirflowException: Bash command failed. The command returned a non-zero exit code 1.
[2025-04-19T12:03:01.329+0000] {taskinstance.py:1226} INFO - Marking task as UP_FOR_RETRY. dag_id=dbt_etl_pipeline_staging, task_id=dbt_staging, run_id=manual__2025-04-18T00:47:21.649681+00:00, execution_date=20250418T004721, start_date=20250419T120237, end_date=20250419T120301
[2025-04-19T12:03:02.187+0000] {taskinstance.py:341} INFO - ::group::Post task execution logs
[2025-04-19T12:03:02.194+0000] {standard_task_runner.py:124} ERROR - Failed to execute job 159 for task dbt_staging (Bash command failed. The command returned a non-zero exit code 1.; 433)
Traceback (most recent call last):
  File "/home/airflow/.local/lib/python3.12/site-packages/airflow/task/task_runner/standard_task_runner.py", line 117, in _start_by_fork
    ret = args.func(args, dag=self.dag)
          ^^^^^^^^^^^^^^^^^^^^^^^^^^^^^
  File "/home/airflow/.local/lib/python3.12/site-packages/airflow/cli/cli_config.py", line 49, in command
    return func(*args, **kwargs)
           ^^^^^^^^^^^^^^^^^^^^^
  File "/home/airflow/.local/lib/python3.12/site-packages/airflow/utils/cli.py", line 116, in wrapper
    return f(*args, **kwargs)
           ^^^^^^^^^^^^^^^^^^
  File "/home/airflow/.local/lib/python3.12/site-packages/airflow/cli/commands/task_command.py", line 483, in task_run
    task_return_code = _run_task_by_selected_method(args, _dag, ti)
                       ^^^^^^^^^^^^^^^^^^^^^^^^^^^^^^^^^^^^^^^^^^^^
  File "/home/airflow/.local/lib/python3.12/site-packages/airflow/cli/commands/task_command.py", line 256, in _run_task_by_selected_method
    return _run_raw_task(args, ti)
           ^^^^^^^^^^^^^^^^^^^^^^^
  File "/home/airflow/.local/lib/python3.12/site-packages/airflow/cli/commands/task_command.py", line 341, in _run_raw_task
    return ti._run_raw_task(
           ^^^^^^^^^^^^^^^^^
  File "/home/airflow/.local/lib/python3.12/site-packages/airflow/utils/session.py", line 97, in wrapper
    return func(*args, session=session, **kwargs)
           ^^^^^^^^^^^^^^^^^^^^^^^^^^^^^^^^^^^^^^
  File "/home/airflow/.local/lib/python3.12/site-packages/airflow/models/taskinstance.py", line 3006, in _run_raw_task
    return _run_raw_task(
           ^^^^^^^^^^^^^^
  File "/home/airflow/.local/lib/python3.12/site-packages/airflow/models/taskinstance.py", line 274, in _run_raw_task
    TaskInstance._execute_task_with_callbacks(
  File "/home/airflow/.local/lib/python3.12/site-packages/airflow/models/taskinstance.py", line 3161, in _execute_task_with_callbacks
    result = self._execute_task(context, task_orig)
             ^^^^^^^^^^^^^^^^^^^^^^^^^^^^^^^^^^^^^^
  File "/home/airflow/.local/lib/python3.12/site-packages/airflow/models/taskinstance.py", line 3185, in _execute_task
    return _execute_task(self, context, task_orig)
           ^^^^^^^^^^^^^^^^^^^^^^^^^^^^^^^^^^^^^^^
  File "/home/airflow/.local/lib/python3.12/site-packages/airflow/models/taskinstance.py", line 768, in _execute_task
    result = _execute_callable(context=context, **execute_callable_kwargs)
             ^^^^^^^^^^^^^^^^^^^^^^^^^^^^^^^^^^^^^^^^^^^^^^^^^^^^^^^^^^^^^
  File "/home/airflow/.local/lib/python3.12/site-packages/airflow/models/taskinstance.py", line 734, in _execute_callable
    return ExecutionCallableRunner(
           ^^^^^^^^^^^^^^^^^^^^^^^^
  File "/home/airflow/.local/lib/python3.12/site-packages/airflow/utils/operator_helpers.py", line 252, in run
    return self.func(*args, **kwargs)
           ^^^^^^^^^^^^^^^^^^^^^^^^^^
  File "/home/airflow/.local/lib/python3.12/site-packages/airflow/models/baseoperator.py", line 424, in wrapper
    return func(self, *args, **kwargs)
           ^^^^^^^^^^^^^^^^^^^^^^^^^^^
  File "/home/airflow/.local/lib/python3.12/site-packages/airflow/operators/bash.py", line 276, in execute
    raise AirflowException(
airflow.exceptions.AirflowException: Bash command failed. The command returned a non-zero exit code 1.
[2025-04-19T12:03:02.256+0000] {local_task_job_runner.py:266} INFO - Task exited with return code 1
[2025-04-19T12:03:02.502+0000] {local_task_job_runner.py:245} INFO - ::endgroup::
[2025-04-19T12:03:02.620+0000] {standard_task_runner.py:217} INFO - Process not found (most likely exited), stop collecting metrics
