[2025-04-18T11:43:58.702+0000] {local_task_job_runner.py:123} INFO - ::group::Pre task execution logs
[2025-04-18T11:43:58.757+0000] {taskinstance.py:2614} INFO - Dependencies all met for dep_context=non-requeueable deps ti=<TaskInstance: dbt_etl_pipeline_mart.dbt_marts_core manual__2025-04-18T11:24:40.132661+00:00 [queued]>
[2025-04-18T11:43:58.768+0000] {taskinstance.py:2614} INFO - Dependencies all met for dep_context=requeueable deps ti=<TaskInstance: dbt_etl_pipeline_mart.dbt_marts_core manual__2025-04-18T11:24:40.132661+00:00 [queued]>
[2025-04-18T11:43:58.769+0000] {taskinstance.py:2867} INFO - Starting attempt 3 of 3
[2025-04-18T11:43:58.782+0000] {taskinstance.py:2890} INFO - Executing <Task(BashOperator): dbt_marts_core> on 2025-04-18 11:24:40.132661+00:00
[2025-04-18T11:43:58.788+0000] {standard_task_runner.py:104} INFO - Running: ['airflow', 'tasks', 'run', 'dbt_etl_pipeline_mart', 'dbt_marts_core', 'manual__2025-04-18T11:24:40.132661+00:00', '--job-id', '123', '--raw', '--subdir', 'DAGS_FOLDER/dbt_marts.py', '--cfg-path', '/tmp/tmpf6a5yhyu']
[2025-04-18T11:43:58.790+0000] {logging_mixin.py:190} WARNING - /home/airflow/.local/lib/python3.12/site-packages/airflow/task/task_runner/standard_task_runner.py:70 DeprecationWarning: This process (pid=362) is multi-threaded, use of fork() may lead to deadlocks in the child.
[2025-04-18T11:43:58.791+0000] {standard_task_runner.py:105} INFO - Job 123: Subtask dbt_marts_core
[2025-04-18T11:43:58.791+0000] {standard_task_runner.py:72} INFO - Started process 363 to run task
[2025-04-18T11:43:59.051+0000] {task_command.py:467} INFO - Running <TaskInstance: dbt_etl_pipeline_mart.dbt_marts_core manual__2025-04-18T11:24:40.132661+00:00 [running]> on host 9c8f13362ff5
[2025-04-18T11:43:59.530+0000] {taskinstance.py:3134} INFO - Exporting env vars: AIRFLOW_CTX_DAG_OWNER='azizjon' AIRFLOW_CTX_DAG_ID='dbt_etl_pipeline_mart' AIRFLOW_CTX_TASK_ID='dbt_marts_core' AIRFLOW_CTX_EXECUTION_DATE='2025-04-18T11:24:40.132661+00:00' AIRFLOW_CTX_TRY_NUMBER='3' AIRFLOW_CTX_DAG_RUN_ID='manual__2025-04-18T11:24:40.132661+00:00'
[2025-04-18T11:43:59.532+0000] {taskinstance.py:732} INFO - ::endgroup::
[2025-04-18T11:43:59.547+0000] {subprocess.py:78} INFO - Tmp dir root location: /tmp
[2025-04-18T11:43:59.548+0000] {subprocess.py:88} INFO - Running command: ['/usr/bin/bash', '-c', '\n        export PATH=/home/airflow/.local/bin:$PATH\n        cd /opt/airflow/commerce_dbt\n        dbt run --select marts.core --profiles-dir .\n        ']
[2025-04-18T11:43:59.560+0000] {subprocess.py:99} INFO - Output:
[2025-04-18T11:44:02.089+0000] {subprocess.py:106} INFO - [0m11:44:02  Running with dbt=1.7.0
[2025-04-18T11:44:02.349+0000] {subprocess.py:106} INFO - [0m11:44:02  Registered adapter: postgres=1.7.0
[2025-04-18T11:44:02.893+0000] {subprocess.py:106} INFO - [0m11:44:02  [[33mWARNING[0m]: Configuration paths exist in your dbt_project.yml file which do not apply to any resources.
[2025-04-18T11:44:02.893+0000] {subprocess.py:106} INFO - There are 1 unused configuration paths:
[2025-04-18T11:44:02.894+0000] {subprocess.py:106} INFO - - seeds.initial_dataset
[2025-04-18T11:44:02.938+0000] {subprocess.py:106} INFO - [0m11:44:02  Found 13 models, 1 snapshot, 6 seeds, 43 tests, 6 sources, 0 exposures, 0 metrics, 401 macros, 0 groups, 0 semantic models
[2025-04-18T11:44:02.941+0000] {subprocess.py:106} INFO - [0m11:44:02
[2025-04-18T11:44:03.534+0000] {subprocess.py:106} INFO - [0m11:44:03  Concurrency: 4 threads (target='dev')
[2025-04-18T11:44:03.535+0000] {subprocess.py:106} INFO - [0m11:44:03
[2025-04-18T11:44:03.551+0000] {subprocess.py:106} INFO - [0m11:44:03  1 of 5 START sql table model commerce_core.dim_customers ....................... [RUN]
[2025-04-18T11:44:03.552+0000] {subprocess.py:106} INFO - [0m11:44:03  2 of 5 START sql table model commerce_core.dim_products ........................ [RUN]
[2025-04-18T11:44:03.553+0000] {subprocess.py:106} INFO - [0m11:44:03  3 of 5 START sql table model commerce_core.dim_stores .......................... [RUN]
[2025-04-18T11:44:03.855+0000] {subprocess.py:106} INFO - [0m11:44:03  2 of 5 OK created sql table model commerce_core.dim_products ................... [[32mSELECT 17[0m in 0.30s]
[2025-04-18T11:44:03.863+0000] {subprocess.py:106} INFO - [0m11:44:03  5 of 5 START sql table model commerce_core.ml_analytics ........................ [RUN]
[2025-04-18T11:44:03.864+0000] {subprocess.py:106} INFO - [0m11:44:03  4 of 5 START sql table model commerce_core.fct_orders .......................... [RUN]
[2025-04-18T11:44:03.869+0000] {subprocess.py:106} INFO - [0m11:44:03  1 of 5 OK created sql table model commerce_core.dim_customers .................. [[32mSELECT 1000[0m in 0.31s]
[2025-04-18T11:44:03.874+0000] {subprocess.py:106} INFO - [0m11:44:03  3 of 5 OK created sql table model commerce_core.dim_stores ..................... [[32mSELECT 5[0m in 0.31s]
[2025-04-18T11:44:04.000+0000] {subprocess.py:106} INFO - [0m11:44:04  5 of 5 ERROR creating sql table model commerce_core.ml_analytics ............... [[31mERROR[0m in 0.13s]
[2025-04-18T11:44:04.055+0000] {subprocess.py:106} INFO - [0m11:44:04  4 of 5 OK created sql table model commerce_core.fct_orders ..................... [[32mSELECT 10000[0m in 0.19s]
[2025-04-18T11:44:04.124+0000] {subprocess.py:106} INFO - [0m11:44:04
[2025-04-18T11:44:04.125+0000] {subprocess.py:106} INFO - [0m11:44:04  Finished running 5 table models in 0 hours 0 minutes and 1.18 seconds (1.18s).
[2025-04-18T11:44:04.198+0000] {subprocess.py:106} INFO - [0m11:44:04
[2025-04-18T11:44:04.199+0000] {subprocess.py:106} INFO - [0m11:44:04  [31mCompleted with 1 error and 0 warnings:[0m
[2025-04-18T11:44:04.199+0000] {subprocess.py:106} INFO - [0m11:44:04
[2025-04-18T11:44:04.200+0000] {subprocess.py:106} INFO - [0m11:44:04    Database Error in model ml_analytics (models/marts/core/ml_analytics.sql)
[2025-04-18T11:44:04.201+0000] {subprocess.py:106} INFO -   column p.product_categories_id does not exist
[2025-04-18T11:44:04.202+0000] {subprocess.py:106} INFO -   LINE 41: JOIN product_categories pc ON p.product_categories_id = pc.p...
[2025-04-18T11:44:04.202+0000] {subprocess.py:106} INFO -                                          ^
[2025-04-18T11:44:04.203+0000] {subprocess.py:106} INFO -   HINT:  Perhaps you meant to reference the column "pc.product_categories_id".
[2025-04-18T11:44:04.203+0000] {subprocess.py:106} INFO -   compiled Code at target/run/commerce_dbt/models/marts/core/ml_analytics.sql
[2025-04-18T11:44:04.204+0000] {subprocess.py:106} INFO - [0m11:44:04
[2025-04-18T11:44:04.205+0000] {subprocess.py:106} INFO - [0m11:44:04  Done. PASS=4 WARN=0 ERROR=1 SKIP=0 TOTAL=5
[2025-04-18T11:44:04.986+0000] {subprocess.py:110} INFO - Command exited with return code 1
[2025-04-18T11:44:05.048+0000] {taskinstance.py:3313} ERROR - Task failed with exception
Traceback (most recent call last):
  File "/home/airflow/.local/lib/python3.12/site-packages/airflow/models/taskinstance.py", line 768, in _execute_task
    result = _execute_callable(context=context, **execute_callable_kwargs)
             ^^^^^^^^^^^^^^^^^^^^^^^^^^^^^^^^^^^^^^^^^^^^^^^^^^^^^^^^^^^^^
  File "/home/airflow/.local/lib/python3.12/site-packages/airflow/models/taskinstance.py", line 734, in _execute_callable
    return ExecutionCallableRunner(
           ^^^^^^^^^^^^^^^^^^^^^^^^
  File "/home/airflow/.local/lib/python3.12/site-packages/airflow/utils/operator_helpers.py", line 252, in run
    return self.func(*args, **kwargs)
           ^^^^^^^^^^^^^^^^^^^^^^^^^^
  File "/home/airflow/.local/lib/python3.12/site-packages/airflow/models/baseoperator.py", line 424, in wrapper
    return func(self, *args, **kwargs)
           ^^^^^^^^^^^^^^^^^^^^^^^^^^^
  File "/home/airflow/.local/lib/python3.12/site-packages/airflow/operators/bash.py", line 276, in execute
    raise AirflowException(
airflow.exceptions.AirflowException: Bash command failed. The command returned a non-zero exit code 1.
[2025-04-18T11:44:05.054+0000] {taskinstance.py:1226} INFO - Marking task as FAILED. dag_id=dbt_etl_pipeline_mart, task_id=dbt_marts_core, run_id=manual__2025-04-18T11:24:40.132661+00:00, execution_date=20250418T112440, start_date=20250418T114358, end_date=20250418T114405
[2025-04-18T11:44:05.184+0000] {taskinstance.py:341} INFO - ::group::Post task execution logs
[2025-04-18T11:44:05.185+0000] {standard_task_runner.py:124} ERROR - Failed to execute job 123 for task dbt_marts_core (Bash command failed. The command returned a non-zero exit code 1.; 363)
Traceback (most recent call last):
  File "/home/airflow/.local/lib/python3.12/site-packages/airflow/task/task_runner/standard_task_runner.py", line 117, in _start_by_fork
    ret = args.func(args, dag=self.dag)
          ^^^^^^^^^^^^^^^^^^^^^^^^^^^^^
  File "/home/airflow/.local/lib/python3.12/site-packages/airflow/cli/cli_config.py", line 49, in command
    return func(*args, **kwargs)
           ^^^^^^^^^^^^^^^^^^^^^
  File "/home/airflow/.local/lib/python3.12/site-packages/airflow/utils/cli.py", line 116, in wrapper
    return f(*args, **kwargs)
           ^^^^^^^^^^^^^^^^^^
  File "/home/airflow/.local/lib/python3.12/site-packages/airflow/cli/commands/task_command.py", line 483, in task_run
    task_return_code = _run_task_by_selected_method(args, _dag, ti)
                       ^^^^^^^^^^^^^^^^^^^^^^^^^^^^^^^^^^^^^^^^^^^^
  File "/home/airflow/.local/lib/python3.12/site-packages/airflow/cli/commands/task_command.py", line 256, in _run_task_by_selected_method
    return _run_raw_task(args, ti)
           ^^^^^^^^^^^^^^^^^^^^^^^
  File "/home/airflow/.local/lib/python3.12/site-packages/airflow/cli/commands/task_command.py", line 341, in _run_raw_task
    return ti._run_raw_task(
           ^^^^^^^^^^^^^^^^^
  File "/home/airflow/.local/lib/python3.12/site-packages/airflow/utils/session.py", line 97, in wrapper
    return func(*args, session=session, **kwargs)
           ^^^^^^^^^^^^^^^^^^^^^^^^^^^^^^^^^^^^^^
  File "/home/airflow/.local/lib/python3.12/site-packages/airflow/models/taskinstance.py", line 3006, in _run_raw_task
    return _run_raw_task(
           ^^^^^^^^^^^^^^
  File "/home/airflow/.local/lib/python3.12/site-packages/airflow/models/taskinstance.py", line 274, in _run_raw_task
    TaskInstance._execute_task_with_callbacks(
  File "/home/airflow/.local/lib/python3.12/site-packages/airflow/models/taskinstance.py", line 3161, in _execute_task_with_callbacks
    result = self._execute_task(context, task_orig)
             ^^^^^^^^^^^^^^^^^^^^^^^^^^^^^^^^^^^^^^
  File "/home/airflow/.local/lib/python3.12/site-packages/airflow/models/taskinstance.py", line 3185, in _execute_task
    return _execute_task(self, context, task_orig)
           ^^^^^^^^^^^^^^^^^^^^^^^^^^^^^^^^^^^^^^^
  File "/home/airflow/.local/lib/python3.12/site-packages/airflow/models/taskinstance.py", line 768, in _execute_task
    result = _execute_callable(context=context, **execute_callable_kwargs)
             ^^^^^^^^^^^^^^^^^^^^^^^^^^^^^^^^^^^^^^^^^^^^^^^^^^^^^^^^^^^^^
  File "/home/airflow/.local/lib/python3.12/site-packages/airflow/models/taskinstance.py", line 734, in _execute_callable
    return ExecutionCallableRunner(
           ^^^^^^^^^^^^^^^^^^^^^^^^
  File "/home/airflow/.local/lib/python3.12/site-packages/airflow/utils/operator_helpers.py", line 252, in run
    return self.func(*args, **kwargs)
           ^^^^^^^^^^^^^^^^^^^^^^^^^^
  File "/home/airflow/.local/lib/python3.12/site-packages/airflow/models/baseoperator.py", line 424, in wrapper
    return func(self, *args, **kwargs)
           ^^^^^^^^^^^^^^^^^^^^^^^^^^^
  File "/home/airflow/.local/lib/python3.12/site-packages/airflow/operators/bash.py", line 276, in execute
    raise AirflowException(
airflow.exceptions.AirflowException: Bash command failed. The command returned a non-zero exit code 1.
[2025-04-18T11:44:05.231+0000] {local_task_job_runner.py:266} INFO - Task exited with return code 1
[2025-04-18T11:44:05.311+0000] {taskinstance.py:3901} INFO - 0 downstream tasks scheduled from follow-on schedule check
[2025-04-18T11:44:05.316+0000] {local_task_job_runner.py:245} INFO - ::endgroup::
