[2025-04-19T15:07:57.732+0000] {local_task_job_runner.py:123} INFO - ::group::Pre task execution logs
[2025-04-19T15:07:57.841+0000] {taskinstance.py:2614} INFO - Dependencies all met for dep_context=non-requeueable deps ti=<TaskInstance: load_new_order_items.dbt_test scheduled__2025-04-19T14:05:00+00:00 [queued]>
[2025-04-19T15:07:57.871+0000] {taskinstance.py:2614} INFO - Dependencies all met for dep_context=requeueable deps ti=<TaskInstance: load_new_order_items.dbt_test scheduled__2025-04-19T14:05:00+00:00 [queued]>
[2025-04-19T15:07:57.872+0000] {taskinstance.py:2867} INFO - Starting attempt 1 of 1
[2025-04-19T15:07:57.897+0000] {taskinstance.py:2890} INFO - Executing <Task(TriggerDagRunOperator): dbt_test> on 2025-04-19 14:05:00+00:00
[2025-04-19T15:07:57.907+0000] {logging_mixin.py:190} WARNING - /home/airflow/.local/lib/python3.12/site-packages/airflow/task/task_runner/standard_task_runner.py:70 DeprecationWarning: This process (pid=729) is multi-threaded, use of fork() may lead to deadlocks in the child.
[2025-04-19T15:07:57.908+0000] {standard_task_runner.py:72} INFO - Started process 730 to run task
[2025-04-19T15:07:57.907+0000] {standard_task_runner.py:104} INFO - Running: ['airflow', 'tasks', 'run', 'load_new_order_items', 'dbt_test', 'scheduled__2025-04-19T14:05:00+00:00', '--job-id', '194', '--raw', '--subdir', 'DAGS_FOLDER/store_to_sql_order_items.py', '--cfg-path', '/tmp/tmp7z7co006']
[2025-04-19T15:07:57.909+0000] {standard_task_runner.py:105} INFO - Job 194: Subtask dbt_test
[2025-04-19T15:07:58.123+0000] {task_command.py:467} INFO - Running <TaskInstance: load_new_order_items.dbt_test scheduled__2025-04-19T14:05:00+00:00 [running]> on host 27536697ee14
[2025-04-19T15:07:58.356+0000] {taskinstance.py:3134} INFO - Exporting env vars: AIRFLOW_CTX_DAG_OWNER='azizjon' AIRFLOW_CTX_DAG_ID='load_new_order_items' AIRFLOW_CTX_TASK_ID='dbt_test' AIRFLOW_CTX_EXECUTION_DATE='2025-04-19T14:05:00+00:00' AIRFLOW_CTX_TRY_NUMBER='1' AIRFLOW_CTX_DAG_RUN_ID='scheduled__2025-04-19T14:05:00+00:00'
[2025-04-19T15:07:58.357+0000] {taskinstance.py:732} INFO - ::endgroup::
[2025-04-19T15:07:58.814+0000] {trigger_dagrun.py:257} INFO - Waiting for dbt_etl_pipeline_test on 2025-04-19 14:05:00+00:00 to become allowed state ['success'] ...
[2025-04-19T15:08:03.878+0000] {trigger_dagrun.py:271} INFO - dbt_etl_pipeline_test finished with allowed state success
[2025-04-19T15:08:03.934+0000] {taskinstance.py:341} INFO - ::group::Post task execution logs
[2025-04-19T15:08:03.935+0000] {taskinstance.py:353} INFO - Marking task as SUCCESS. dag_id=load_new_order_items, task_id=dbt_test, run_id=scheduled__2025-04-19T14:05:00+00:00, execution_date=20250419T140500, start_date=20250419T150757, end_date=20250419T150803
[2025-04-19T15:08:04.094+0000] {local_task_job_runner.py:266} INFO - Task exited with return code 0
[2025-04-19T15:08:04.260+0000] {taskinstance.py:3901} INFO - 0 downstream tasks scheduled from follow-on schedule check
[2025-04-19T15:08:04.263+0000] {local_task_job_runner.py:245} INFO - ::endgroup::
[2025-04-19T15:59:26.490+0000] {local_task_job_runner.py:123} INFO - ::group::Pre task execution logs
[2025-04-19T15:59:26.588+0000] {taskinstance.py:2614} INFO - Dependencies all met for dep_context=non-requeueable deps ti=<TaskInstance: load_new_order_items.dbt_test scheduled__2025-04-19T14:05:00+00:00 [queued]>
[2025-04-19T15:59:26.610+0000] {taskinstance.py:2614} INFO - Dependencies all met for dep_context=requeueable deps ti=<TaskInstance: load_new_order_items.dbt_test scheduled__2025-04-19T14:05:00+00:00 [queued]>
[2025-04-19T15:59:26.611+0000] {taskinstance.py:2867} INFO - Starting attempt 1 of 1
[2025-04-19T15:59:26.638+0000] {taskinstance.py:2890} INFO - Executing <Task(TriggerDagRunOperator): dbt_test> on 2025-04-19 14:05:00+00:00
[2025-04-19T15:59:26.648+0000] {logging_mixin.py:190} WARNING - /home/airflow/.local/lib/python3.12/site-packages/airflow/task/task_runner/standard_task_runner.py:70 DeprecationWarning: This process (pid=5769) is multi-threaded, use of fork() may lead to deadlocks in the child.
[2025-04-19T15:59:26.649+0000] {standard_task_runner.py:72} INFO - Started process 5770 to run task
[2025-04-19T15:59:26.649+0000] {standard_task_runner.py:104} INFO - Running: ['airflow', 'tasks', 'run', 'load_new_order_items', 'dbt_test', 'scheduled__2025-04-19T14:05:00+00:00', '--job-id', '255', '--raw', '--subdir', 'DAGS_FOLDER/store_to_sql_order_items.py', '--cfg-path', '/tmp/tmprczyr_p0']
[2025-04-19T15:59:26.651+0000] {standard_task_runner.py:105} INFO - Job 255: Subtask dbt_test
[2025-04-19T15:59:26.895+0000] {task_command.py:467} INFO - Running <TaskInstance: load_new_order_items.dbt_test scheduled__2025-04-19T14:05:00+00:00 [running]> on host 27536697ee14
[2025-04-19T15:59:27.164+0000] {taskinstance.py:3134} INFO - Exporting env vars: AIRFLOW_CTX_DAG_OWNER='azizjon' AIRFLOW_CTX_DAG_ID='load_new_order_items' AIRFLOW_CTX_TASK_ID='dbt_test' AIRFLOW_CTX_EXECUTION_DATE='2025-04-19T14:05:00+00:00' AIRFLOW_CTX_TRY_NUMBER='1' AIRFLOW_CTX_DAG_RUN_ID='scheduled__2025-04-19T14:05:00+00:00'
[2025-04-19T15:59:27.165+0000] {taskinstance.py:732} INFO - ::endgroup::
[2025-04-19T15:59:27.680+0000] {trigger_dagrun.py:257} INFO - Waiting for dbt_etl_pipeline_test on 2025-04-19 14:05:00+00:00 to become allowed state ['success'] ...
[2025-04-19T15:59:32.742+0000] {trigger_dagrun.py:257} INFO - Waiting for dbt_etl_pipeline_test on 2025-04-19 14:05:00+00:00 to become allowed state ['success'] ...
[2025-04-19T15:59:37.806+0000] {trigger_dagrun.py:257} INFO - Waiting for dbt_etl_pipeline_test on 2025-04-19 14:05:00+00:00 to become allowed state ['success'] ...
[2025-04-19T15:59:42.868+0000] {trigger_dagrun.py:257} INFO - Waiting for dbt_etl_pipeline_test on 2025-04-19 14:05:00+00:00 to become allowed state ['success'] ...
[2025-04-19T15:59:47.934+0000] {trigger_dagrun.py:257} INFO - Waiting for dbt_etl_pipeline_test on 2025-04-19 14:05:00+00:00 to become allowed state ['success'] ...
[2025-04-19T15:59:53.694+0000] {trigger_dagrun.py:257} INFO - Waiting for dbt_etl_pipeline_test on 2025-04-19 14:05:00+00:00 to become allowed state ['success'] ...
[2025-04-19T15:59:58.763+0000] {trigger_dagrun.py:257} INFO - Waiting for dbt_etl_pipeline_test on 2025-04-19 14:05:00+00:00 to become allowed state ['success'] ...
[2025-04-19T16:00:03.830+0000] {trigger_dagrun.py:257} INFO - Waiting for dbt_etl_pipeline_test on 2025-04-19 14:05:00+00:00 to become allowed state ['success'] ...
[2025-04-19T16:00:08.935+0000] {trigger_dagrun.py:257} INFO - Waiting for dbt_etl_pipeline_test on 2025-04-19 14:05:00+00:00 to become allowed state ['success'] ...
[2025-04-19T16:00:14.032+0000] {trigger_dagrun.py:257} INFO - Waiting for dbt_etl_pipeline_test on 2025-04-19 14:05:00+00:00 to become allowed state ['success'] ...
[2025-04-19T16:00:19.123+0000] {trigger_dagrun.py:257} INFO - Waiting for dbt_etl_pipeline_test on 2025-04-19 14:05:00+00:00 to become allowed state ['success'] ...
[2025-04-19T16:00:24.200+0000] {trigger_dagrun.py:257} INFO - Waiting for dbt_etl_pipeline_test on 2025-04-19 14:05:00+00:00 to become allowed state ['success'] ...
[2025-04-19T16:00:29.280+0000] {trigger_dagrun.py:257} INFO - Waiting for dbt_etl_pipeline_test on 2025-04-19 14:05:00+00:00 to become allowed state ['success'] ...
[2025-04-19T16:00:34.349+0000] {trigger_dagrun.py:257} INFO - Waiting for dbt_etl_pipeline_test on 2025-04-19 14:05:00+00:00 to become allowed state ['success'] ...
[2025-04-19T16:00:39.415+0000] {trigger_dagrun.py:257} INFO - Waiting for dbt_etl_pipeline_test on 2025-04-19 14:05:00+00:00 to become allowed state ['success'] ...
[2025-04-19T16:00:44.484+0000] {trigger_dagrun.py:257} INFO - Waiting for dbt_etl_pipeline_test on 2025-04-19 14:05:00+00:00 to become allowed state ['success'] ...
[2025-04-19T16:00:49.559+0000] {trigger_dagrun.py:257} INFO - Waiting for dbt_etl_pipeline_test on 2025-04-19 14:05:00+00:00 to become allowed state ['success'] ...
[2025-04-19T16:00:54.645+0000] {trigger_dagrun.py:257} INFO - Waiting for dbt_etl_pipeline_test on 2025-04-19 14:05:00+00:00 to become allowed state ['success'] ...
[2025-04-19T16:00:59.751+0000] {trigger_dagrun.py:257} INFO - Waiting for dbt_etl_pipeline_test on 2025-04-19 14:05:00+00:00 to become allowed state ['success'] ...
[2025-04-19T16:01:04.810+0000] {trigger_dagrun.py:257} INFO - Waiting for dbt_etl_pipeline_test on 2025-04-19 14:05:00+00:00 to become allowed state ['success'] ...
[2025-04-19T16:01:09.926+0000] {taskinstance.py:3313} ERROR - Task failed with exception
Traceback (most recent call last):
  File "/home/airflow/.local/lib/python3.12/site-packages/airflow/models/taskinstance.py", line 768, in _execute_task
    result = _execute_callable(context=context, **execute_callable_kwargs)
             ^^^^^^^^^^^^^^^^^^^^^^^^^^^^^^^^^^^^^^^^^^^^^^^^^^^^^^^^^^^^^
  File "/home/airflow/.local/lib/python3.12/site-packages/airflow/models/taskinstance.py", line 734, in _execute_callable
    return ExecutionCallableRunner(
           ^^^^^^^^^^^^^^^^^^^^^^^^
  File "/home/airflow/.local/lib/python3.12/site-packages/airflow/utils/operator_helpers.py", line 252, in run
    return self.func(*args, **kwargs)
           ^^^^^^^^^^^^^^^^^^^^^^^^^^
  File "/home/airflow/.local/lib/python3.12/site-packages/airflow/models/baseoperator.py", line 424, in wrapper
    return func(self, *args, **kwargs)
           ^^^^^^^^^^^^^^^^^^^^^^^^^^^
  File "/home/airflow/.local/lib/python3.12/site-packages/airflow/operators/trigger_dagrun.py", line 266, in execute
    dag_run.refresh_from_db()
  File "/home/airflow/.local/lib/python3.12/site-packages/airflow/utils/session.py", line 97, in wrapper
    return func(*args, session=session, **kwargs)
           ^^^^^^^^^^^^^^^^^^^^^^^^^^^^^^^^^^^^^^
  File "/home/airflow/.local/lib/python3.12/site-packages/airflow/models/dagrun.py", line 361, in refresh_from_db
    ).one()
      ^^^^^
  File "/home/airflow/.local/lib/python3.12/site-packages/sqlalchemy/engine/result.py", line 1522, in one
    return self._only_one_row(
           ^^^^^^^^^^^^^^^^^^^
  File "/home/airflow/.local/lib/python3.12/site-packages/sqlalchemy/engine/result.py", line 562, in _only_one_row
    raise exc.NoResultFound(
sqlalchemy.exc.NoResultFound: No row was found when one was required
[2025-04-19T16:01:10.013+0000] {taskinstance.py:1226} INFO - Marking task as FAILED. dag_id=load_new_order_items, task_id=dbt_test, run_id=scheduled__2025-04-19T14:05:00+00:00, execution_date=20250419T140500, start_date=20250419T155926, end_date=20250419T160110
[2025-04-19T16:01:10.028+0000] {taskinstance.py:341} INFO - ::group::Post task execution logs
[2025-04-19T16:01:10.029+0000] {standard_task_runner.py:124} ERROR - Failed to execute job 255 for task dbt_test ((psycopg2.errors.ForeignKeyViolation) insert or update on table "task_fail" violates foreign key constraint "task_fail_ti_fkey"
DETAIL:  Key (dag_id, task_id, run_id, map_index)=(load_new_order_items, dbt_test, scheduled__2025-04-19T14:05:00+00:00, -1) is not present in table "task_instance".

[SQL: INSERT INTO task_fail (task_id, dag_id, run_id, map_index, start_date, end_date, duration) VALUES (%(task_id)s, %(dag_id)s, %(run_id)s, %(map_index)s, %(start_date)s, %(end_date)s, %(duration)s) RETURNING task_fail.id]
[parameters: {'task_id': 'dbt_test', 'dag_id': 'load_new_order_items', 'run_id': 'scheduled__2025-04-19T14:05:00+00:00', 'map_index': -1, 'start_date': datetime.datetime(2025, 4, 19, 15, 59, 26, 588994, tzinfo=Timezone('UTC')), 'end_date': datetime.datetime(2025, 4, 19, 16, 1, 10, 12562, tzinfo=Timezone('UTC')), 'duration': 103}]
(Background on this error at: https://sqlalche.me/e/14/gkpj); 5770)
Traceback (most recent call last):
  File "/home/airflow/.local/lib/python3.12/site-packages/airflow/models/taskinstance.py", line 274, in _run_raw_task
    TaskInstance._execute_task_with_callbacks(
  File "/home/airflow/.local/lib/python3.12/site-packages/airflow/models/taskinstance.py", line 3161, in _execute_task_with_callbacks
    result = self._execute_task(context, task_orig)
             ^^^^^^^^^^^^^^^^^^^^^^^^^^^^^^^^^^^^^^
  File "/home/airflow/.local/lib/python3.12/site-packages/airflow/models/taskinstance.py", line 3185, in _execute_task
    return _execute_task(self, context, task_orig)
           ^^^^^^^^^^^^^^^^^^^^^^^^^^^^^^^^^^^^^^^
  File "/home/airflow/.local/lib/python3.12/site-packages/airflow/models/taskinstance.py", line 768, in _execute_task
    result = _execute_callable(context=context, **execute_callable_kwargs)
             ^^^^^^^^^^^^^^^^^^^^^^^^^^^^^^^^^^^^^^^^^^^^^^^^^^^^^^^^^^^^^
  File "/home/airflow/.local/lib/python3.12/site-packages/airflow/models/taskinstance.py", line 734, in _execute_callable
    return ExecutionCallableRunner(
           ^^^^^^^^^^^^^^^^^^^^^^^^
  File "/home/airflow/.local/lib/python3.12/site-packages/airflow/utils/operator_helpers.py", line 252, in run
    return self.func(*args, **kwargs)
           ^^^^^^^^^^^^^^^^^^^^^^^^^^
  File "/home/airflow/.local/lib/python3.12/site-packages/airflow/models/baseoperator.py", line 424, in wrapper
    return func(self, *args, **kwargs)
           ^^^^^^^^^^^^^^^^^^^^^^^^^^^
  File "/home/airflow/.local/lib/python3.12/site-packages/airflow/operators/trigger_dagrun.py", line 266, in execute
    dag_run.refresh_from_db()
  File "/home/airflow/.local/lib/python3.12/site-packages/airflow/utils/session.py", line 97, in wrapper
    return func(*args, session=session, **kwargs)
           ^^^^^^^^^^^^^^^^^^^^^^^^^^^^^^^^^^^^^^
  File "/home/airflow/.local/lib/python3.12/site-packages/airflow/models/dagrun.py", line 361, in refresh_from_db
    ).one()
      ^^^^^
  File "/home/airflow/.local/lib/python3.12/site-packages/sqlalchemy/engine/result.py", line 1522, in one
    return self._only_one_row(
           ^^^^^^^^^^^^^^^^^^^
  File "/home/airflow/.local/lib/python3.12/site-packages/sqlalchemy/engine/result.py", line 562, in _only_one_row
    raise exc.NoResultFound(
sqlalchemy.exc.NoResultFound: No row was found when one was required

During handling of the above exception, another exception occurred:

Traceback (most recent call last):
  File "/home/airflow/.local/lib/python3.12/site-packages/sqlalchemy/engine/base.py", line 1910, in _execute_context
    self.dialect.do_execute(
  File "/home/airflow/.local/lib/python3.12/site-packages/sqlalchemy/engine/default.py", line 736, in do_execute
    cursor.execute(statement, parameters)
psycopg2.errors.ForeignKeyViolation: insert or update on table "task_fail" violates foreign key constraint "task_fail_ti_fkey"
DETAIL:  Key (dag_id, task_id, run_id, map_index)=(load_new_order_items, dbt_test, scheduled__2025-04-19T14:05:00+00:00, -1) is not present in table "task_instance".


The above exception was the direct cause of the following exception:

Traceback (most recent call last):
  File "/home/airflow/.local/lib/python3.12/site-packages/airflow/task/task_runner/standard_task_runner.py", line 117, in _start_by_fork
    ret = args.func(args, dag=self.dag)
          ^^^^^^^^^^^^^^^^^^^^^^^^^^^^^
  File "/home/airflow/.local/lib/python3.12/site-packages/airflow/cli/cli_config.py", line 49, in command
    return func(*args, **kwargs)
           ^^^^^^^^^^^^^^^^^^^^^
  File "/home/airflow/.local/lib/python3.12/site-packages/airflow/utils/cli.py", line 116, in wrapper
    return f(*args, **kwargs)
           ^^^^^^^^^^^^^^^^^^
  File "/home/airflow/.local/lib/python3.12/site-packages/airflow/cli/commands/task_command.py", line 483, in task_run
    task_return_code = _run_task_by_selected_method(args, _dag, ti)
                       ^^^^^^^^^^^^^^^^^^^^^^^^^^^^^^^^^^^^^^^^^^^^
  File "/home/airflow/.local/lib/python3.12/site-packages/airflow/cli/commands/task_command.py", line 256, in _run_task_by_selected_method
    return _run_raw_task(args, ti)
           ^^^^^^^^^^^^^^^^^^^^^^^
  File "/home/airflow/.local/lib/python3.12/site-packages/airflow/cli/commands/task_command.py", line 341, in _run_raw_task
    return ti._run_raw_task(
           ^^^^^^^^^^^^^^^^^
  File "/home/airflow/.local/lib/python3.12/site-packages/airflow/utils/session.py", line 97, in wrapper
    return func(*args, session=session, **kwargs)
           ^^^^^^^^^^^^^^^^^^^^^^^^^^^^^^^^^^^^^^
  File "/home/airflow/.local/lib/python3.12/site-packages/airflow/models/taskinstance.py", line 3006, in _run_raw_task
    return _run_raw_task(
           ^^^^^^^^^^^^^^
  File "/home/airflow/.local/lib/python3.12/site-packages/airflow/models/taskinstance.py", line 337, in _run_raw_task
    ti.handle_failure(e, test_mode, context, session=session)
  File "/home/airflow/.local/lib/python3.12/site-packages/airflow/utils/session.py", line 94, in wrapper
    return func(*args, **kwargs)
           ^^^^^^^^^^^^^^^^^^^^^
  File "/home/airflow/.local/lib/python3.12/site-packages/airflow/models/taskinstance.py", line 3434, in handle_failure
    _handle_failure(
  File "/home/airflow/.local/lib/python3.12/site-packages/airflow/utils/session.py", line 94, in wrapper
    return func(*args, **kwargs)
           ^^^^^^^^^^^^^^^^^^^^^
  File "/home/airflow/.local/lib/python3.12/site-packages/airflow/api_internal/internal_api_call.py", line 166, in wrapper
    return func(*args, **kwargs)
           ^^^^^^^^^^^^^^^^^^^^^
  File "/home/airflow/.local/lib/python3.12/site-packages/airflow/models/taskinstance.py", line 1244, in _handle_failure
    TaskInstance.save_to_db(task_instance, session)
  File "/home/airflow/.local/lib/python3.12/site-packages/airflow/api_internal/internal_api_call.py", line 166, in wrapper
    return func(*args, **kwargs)
           ^^^^^^^^^^^^^^^^^^^^^
  File "/home/airflow/.local/lib/python3.12/site-packages/airflow/utils/session.py", line 94, in wrapper
    return func(*args, **kwargs)
           ^^^^^^^^^^^^^^^^^^^^^
  File "/home/airflow/.local/lib/python3.12/site-packages/airflow/models/taskinstance.py", line 3402, in save_to_db
    ti.get_dagrun().refresh_from_db()
    ^^^^^^^^^^^^^^^
  File "/home/airflow/.local/lib/python3.12/site-packages/airflow/utils/session.py", line 96, in wrapper
    with create_session() as session:
         ^^^^^^^^^^^^^^^^
  File "/usr/local/lib/python3.12/contextlib.py", line 144, in __exit__
    next(self.gen)
  File "/home/airflow/.local/lib/python3.12/site-packages/airflow/utils/session.py", line 57, in create_session
    session.commit()
  File "/home/airflow/.local/lib/python3.12/site-packages/sqlalchemy/orm/session.py", line 1454, in commit
    self._transaction.commit(_to_root=self.future)
  File "/home/airflow/.local/lib/python3.12/site-packages/sqlalchemy/orm/session.py", line 832, in commit
    self._prepare_impl()
  File "/home/airflow/.local/lib/python3.12/site-packages/sqlalchemy/orm/session.py", line 811, in _prepare_impl
    self.session.flush()
  File "/home/airflow/.local/lib/python3.12/site-packages/sqlalchemy/orm/session.py", line 3449, in flush
    self._flush(objects)
  File "/home/airflow/.local/lib/python3.12/site-packages/sqlalchemy/orm/session.py", line 3588, in _flush
    with util.safe_reraise():
         ^^^^^^^^^^^^^^^^^^^
  File "/home/airflow/.local/lib/python3.12/site-packages/sqlalchemy/util/langhelpers.py", line 70, in __exit__
    compat.raise_(
  File "/home/airflow/.local/lib/python3.12/site-packages/sqlalchemy/util/compat.py", line 211, in raise_
    raise exception
  File "/home/airflow/.local/lib/python3.12/site-packages/sqlalchemy/orm/session.py", line 3549, in _flush
    flush_context.execute()
  File "/home/airflow/.local/lib/python3.12/site-packages/sqlalchemy/orm/unitofwork.py", line 456, in execute
    rec.execute(self)
  File "/home/airflow/.local/lib/python3.12/site-packages/sqlalchemy/orm/unitofwork.py", line 630, in execute
    util.preloaded.orm_persistence.save_obj(
  File "/home/airflow/.local/lib/python3.12/site-packages/sqlalchemy/orm/persistence.py", line 245, in save_obj
    _emit_insert_statements(
  File "/home/airflow/.local/lib/python3.12/site-packages/sqlalchemy/orm/persistence.py", line 1238, in _emit_insert_statements
    result = connection._execute_20(
             ^^^^^^^^^^^^^^^^^^^^^^^
  File "/home/airflow/.local/lib/python3.12/site-packages/sqlalchemy/engine/base.py", line 1710, in _execute_20
    return meth(self, args_10style, kwargs_10style, execution_options)
           ^^^^^^^^^^^^^^^^^^^^^^^^^^^^^^^^^^^^^^^^^^^^^^^^^^^^^^^^^^^
  File "/home/airflow/.local/lib/python3.12/site-packages/sqlalchemy/sql/elements.py", line 334, in _execute_on_connection
    return connection._execute_clauseelement(
           ^^^^^^^^^^^^^^^^^^^^^^^^^^^^^^^^^^
  File "/home/airflow/.local/lib/python3.12/site-packages/sqlalchemy/engine/base.py", line 1577, in _execute_clauseelement
    ret = self._execute_context(
          ^^^^^^^^^^^^^^^^^^^^^^
  File "/home/airflow/.local/lib/python3.12/site-packages/sqlalchemy/engine/base.py", line 1953, in _execute_context
    self._handle_dbapi_exception(
  File "/home/airflow/.local/lib/python3.12/site-packages/sqlalchemy/engine/base.py", line 2134, in _handle_dbapi_exception
    util.raise_(
  File "/home/airflow/.local/lib/python3.12/site-packages/sqlalchemy/util/compat.py", line 211, in raise_
    raise exception
  File "/home/airflow/.local/lib/python3.12/site-packages/sqlalchemy/engine/base.py", line 1910, in _execute_context
    self.dialect.do_execute(
  File "/home/airflow/.local/lib/python3.12/site-packages/sqlalchemy/engine/default.py", line 736, in do_execute
    cursor.execute(statement, parameters)
sqlalchemy.exc.IntegrityError: (psycopg2.errors.ForeignKeyViolation) insert or update on table "task_fail" violates foreign key constraint "task_fail_ti_fkey"
DETAIL:  Key (dag_id, task_id, run_id, map_index)=(load_new_order_items, dbt_test, scheduled__2025-04-19T14:05:00+00:00, -1) is not present in table "task_instance".

[SQL: INSERT INTO task_fail (task_id, dag_id, run_id, map_index, start_date, end_date, duration) VALUES (%(task_id)s, %(dag_id)s, %(run_id)s, %(map_index)s, %(start_date)s, %(end_date)s, %(duration)s) RETURNING task_fail.id]
[parameters: {'task_id': 'dbt_test', 'dag_id': 'load_new_order_items', 'run_id': 'scheduled__2025-04-19T14:05:00+00:00', 'map_index': -1, 'start_date': datetime.datetime(2025, 4, 19, 15, 59, 26, 588994, tzinfo=Timezone('UTC')), 'end_date': datetime.datetime(2025, 4, 19, 16, 1, 10, 12562, tzinfo=Timezone('UTC')), 'duration': 103}]
(Background on this error at: https://sqlalche.me/e/14/gkpj)
[2025-04-19T16:01:10.056+0000] {local_task_job_runner.py:266} INFO - Task exited with return code 1
[2025-04-19T16:01:10.138+0000] {local_task_job_runner.py:245} INFO - ::endgroup::
