[2025-04-19T15:19:55.769+0000] {local_task_job_runner.py:123} INFO - ::group::Pre task execution logs
[2025-04-19T15:19:55.832+0000] {taskinstance.py:2614} INFO - Dependencies all met for dep_context=non-requeueable deps ti=<TaskInstance: load_new_orders.dbt_test manual__2025-04-19T15:19:04.998325+00:00 [queued]>
[2025-04-19T15:19:55.846+0000] {taskinstance.py:2614} INFO - Dependencies all met for dep_context=requeueable deps ti=<TaskInstance: load_new_orders.dbt_test manual__2025-04-19T15:19:04.998325+00:00 [queued]>
[2025-04-19T15:19:55.849+0000] {taskinstance.py:2867} INFO - Starting attempt 1 of 1
[2025-04-19T15:19:55.865+0000] {taskinstance.py:2890} INFO - Executing <Task(TriggerDagRunOperator): dbt_test> on 2025-04-19 15:19:04.998325+00:00
[2025-04-19T15:19:55.874+0000] {logging_mixin.py:190} WARNING - /home/airflow/.local/lib/python3.12/site-packages/airflow/task/task_runner/standard_task_runner.py:70 DeprecationWarning: This process (pid=2126) is multi-threaded, use of fork() may lead to deadlocks in the child.
[2025-04-19T15:19:55.876+0000] {standard_task_runner.py:72} INFO - Started process 2127 to run task
[2025-04-19T15:19:55.875+0000] {standard_task_runner.py:104} INFO - Running: ['airflow', 'tasks', 'run', 'load_new_orders', 'dbt_test', 'manual__2025-04-19T15:19:04.998325+00:00', '--job-id', '215', '--raw', '--subdir', 'DAGS_FOLDER/store_to_sql_orders.py', '--cfg-path', '/tmp/tmpcnldxft6']
[2025-04-19T15:19:55.878+0000] {standard_task_runner.py:105} INFO - Job 215: Subtask dbt_test
[2025-04-19T15:19:56.143+0000] {task_command.py:467} INFO - Running <TaskInstance: load_new_orders.dbt_test manual__2025-04-19T15:19:04.998325+00:00 [running]> on host 27536697ee14
[2025-04-19T15:19:56.551+0000] {taskinstance.py:3134} INFO - Exporting env vars: AIRFLOW_CTX_DAG_OWNER='azizjon' AIRFLOW_CTX_DAG_ID='load_new_orders' AIRFLOW_CTX_TASK_ID='dbt_test' AIRFLOW_CTX_EXECUTION_DATE='2025-04-19T15:19:04.998325+00:00' AIRFLOW_CTX_TRY_NUMBER='1' AIRFLOW_CTX_DAG_RUN_ID='manual__2025-04-19T15:19:04.998325+00:00'
[2025-04-19T15:19:56.552+0000] {taskinstance.py:732} INFO - ::endgroup::
[2025-04-19T15:19:57.036+0000] {trigger_dagrun.py:257} INFO - Waiting for dbt_etl_pipeline_test on 2025-04-19 15:19:04.998325+00:00 to become allowed state ['success'] ...
[2025-04-19T15:20:02.090+0000] {trigger_dagrun.py:257} INFO - Waiting for dbt_etl_pipeline_test on 2025-04-19 15:19:04.998325+00:00 to become allowed state ['success'] ...
[2025-04-19T15:20:07.165+0000] {trigger_dagrun.py:257} INFO - Waiting for dbt_etl_pipeline_test on 2025-04-19 15:19:04.998325+00:00 to become allowed state ['success'] ...
[2025-04-19T15:20:11.283+0000] {local_task_job_runner.py:346} WARNING - State of this instance has been externally set to None. Terminating instance.
[2025-04-19T15:20:11.284+0000] {local_task_job_runner.py:245} INFO - ::endgroup::
[2025-04-19T15:20:11.285+0000] {process_utils.py:132} INFO - Sending 15 to group 2127. PIDs of all processes in the group: [2127]
[2025-04-19T15:20:11.286+0000] {process_utils.py:87} INFO - Sending the signal 15 to group 2127
[2025-04-19T15:20:11.287+0000] {taskinstance.py:3094} ERROR - Received SIGTERM. Terminating subprocesses.
[2025-04-19T15:20:11.290+0000] {taskinstance.py:3095} ERROR - Stacktrace: 
  File "/home/airflow/.local/bin/airflow", line 8, in <module>
    sys.exit(main())
  File "/home/airflow/.local/lib/python3.12/site-packages/airflow/__main__.py", line 62, in main
    args.func(args)
  File "/home/airflow/.local/lib/python3.12/site-packages/airflow/cli/cli_config.py", line 49, in command
    return func(*args, **kwargs)
  File "/home/airflow/.local/lib/python3.12/site-packages/airflow/utils/cli.py", line 116, in wrapper
    return f(*args, **kwargs)
  File "/home/airflow/.local/lib/python3.12/site-packages/airflow/utils/providers_configuration_loader.py", line 55, in wrapped_function
    return func(*args, **kwargs)
  File "/home/airflow/.local/lib/python3.12/site-packages/airflow/cli/commands/scheduler_command.py", line 56, in scheduler
    run_command_with_daemon_option(
  File "/home/airflow/.local/lib/python3.12/site-packages/airflow/cli/commands/daemon_utils.py", line 86, in run_command_with_daemon_option
    callback()
  File "/home/airflow/.local/lib/python3.12/site-packages/airflow/cli/commands/scheduler_command.py", line 59, in <lambda>
    callback=lambda: _run_scheduler_job(args),
  File "/home/airflow/.local/lib/python3.12/site-packages/airflow/cli/commands/scheduler_command.py", line 47, in _run_scheduler_job
    run_job(job=job_runner.job, execute_callable=job_runner._execute)
  File "/home/airflow/.local/lib/python3.12/site-packages/airflow/utils/session.py", line 97, in wrapper
    return func(*args, session=session, **kwargs)
  File "/home/airflow/.local/lib/python3.12/site-packages/airflow/jobs/job.py", line 421, in run_job
    return execute_job(job, execute_callable=execute_callable)
  File "/home/airflow/.local/lib/python3.12/site-packages/airflow/jobs/job.py", line 450, in execute_job
    ret = execute_callable()
  File "/home/airflow/.local/lib/python3.12/site-packages/airflow/jobs/scheduler_job_runner.py", line 990, in _execute
    executor.start()
  File "/home/airflow/.local/lib/python3.12/site-packages/airflow/executors/local_executor.py", line 392, in start
    self.impl.start()
  File "/home/airflow/.local/lib/python3.12/site-packages/airflow/executors/local_executor.py", line 330, in start
    worker.start()
  File "/usr/local/lib/python3.12/multiprocessing/process.py", line 121, in start
    self._popen = self._Popen(self)
  File "/usr/local/lib/python3.12/multiprocessing/context.py", line 224, in _Popen
    return _default_context.get_context().Process._Popen(process_obj)
  File "/usr/local/lib/python3.12/multiprocessing/context.py", line 282, in _Popen
    return Popen(process_obj)
  File "/usr/local/lib/python3.12/multiprocessing/popen_fork.py", line 19, in __init__
    self._launch(process_obj)
  File "/usr/local/lib/python3.12/multiprocessing/popen_fork.py", line 71, in _launch
    code = process_obj._bootstrap(parent_sentinel=child_r)
  File "/usr/local/lib/python3.12/multiprocessing/process.py", line 314, in _bootstrap
    self.run()
  File "/home/airflow/.local/lib/python3.12/site-packages/airflow/executors/local_executor.py", line 80, in run
    return super().run()
  File "/usr/local/lib/python3.12/multiprocessing/process.py", line 108, in run
    self._target(*self._args, **self._kwargs)
  File "/home/airflow/.local/lib/python3.12/site-packages/airflow/traces/tracer.py", line 58, in wrapper
    return func(*args, **kwargs)
  File "/home/airflow/.local/lib/python3.12/site-packages/airflow/executors/local_executor.py", line 211, in do_work
    self.execute_work(key=key, command=command)
  File "/home/airflow/.local/lib/python3.12/site-packages/airflow/traces/tracer.py", line 58, in wrapper
    return func(*args, **kwargs)
  File "/home/airflow/.local/lib/python3.12/site-packages/airflow/executors/local_executor.py", line 100, in execute_work
    state = self._execute_work_in_fork(command)
  File "/home/airflow/.local/lib/python3.12/site-packages/airflow/traces/tracer.py", line 58, in wrapper
    return func(*args, **kwargs)
  File "/home/airflow/.local/lib/python3.12/site-packages/airflow/executors/local_executor.py", line 142, in _execute_work_in_fork
    args.func(args)
  File "/home/airflow/.local/lib/python3.12/site-packages/airflow/cli/cli_config.py", line 49, in command
    return func(*args, **kwargs)
  File "/home/airflow/.local/lib/python3.12/site-packages/airflow/utils/cli.py", line 116, in wrapper
    return f(*args, **kwargs)
  File "/home/airflow/.local/lib/python3.12/site-packages/airflow/cli/commands/task_command.py", line 483, in task_run
    task_return_code = _run_task_by_selected_method(args, _dag, ti)
  File "/home/airflow/.local/lib/python3.12/site-packages/airflow/cli/commands/task_command.py", line 254, in _run_task_by_selected_method
    return _run_task_by_local_task_job(args, ti)
  File "/home/airflow/.local/lib/python3.12/site-packages/airflow/cli/commands/task_command.py", line 322, in _run_task_by_local_task_job
    ret = run_job(job=job_runner.job, execute_callable=job_runner._execute)
  File "/home/airflow/.local/lib/python3.12/site-packages/airflow/utils/session.py", line 97, in wrapper
    return func(*args, session=session, **kwargs)
  File "/home/airflow/.local/lib/python3.12/site-packages/airflow/jobs/job.py", line 421, in run_job
    return execute_job(job, execute_callable=execute_callable)
  File "/home/airflow/.local/lib/python3.12/site-packages/airflow/jobs/job.py", line 450, in execute_job
    ret = execute_callable()
  File "/home/airflow/.local/lib/python3.12/site-packages/airflow/jobs/local_task_job_runner.py", line 171, in _execute
    self.task_runner.start()
  File "/home/airflow/.local/lib/python3.12/site-packages/airflow/task/task_runner/standard_task_runner.py", line 55, in start
    self.process = self._start_by_fork()
  File "/home/airflow/.local/lib/python3.12/site-packages/airflow/task/task_runner/standard_task_runner.py", line 117, in _start_by_fork
    ret = args.func(args, dag=self.dag)
  File "/home/airflow/.local/lib/python3.12/site-packages/airflow/cli/cli_config.py", line 49, in command
    return func(*args, **kwargs)
  File "/home/airflow/.local/lib/python3.12/site-packages/airflow/utils/cli.py", line 116, in wrapper
    return f(*args, **kwargs)
  File "/home/airflow/.local/lib/python3.12/site-packages/airflow/cli/commands/task_command.py", line 483, in task_run
    task_return_code = _run_task_by_selected_method(args, _dag, ti)
  File "/home/airflow/.local/lib/python3.12/site-packages/airflow/cli/commands/task_command.py", line 256, in _run_task_by_selected_method
    return _run_raw_task(args, ti)
  File "/home/airflow/.local/lib/python3.12/site-packages/airflow/cli/commands/task_command.py", line 341, in _run_raw_task
    return ti._run_raw_task(
  File "/home/airflow/.local/lib/python3.12/site-packages/airflow/utils/session.py", line 97, in wrapper
    return func(*args, session=session, **kwargs)
  File "/home/airflow/.local/lib/python3.12/site-packages/airflow/models/taskinstance.py", line 3006, in _run_raw_task
    return _run_raw_task(
  File "/home/airflow/.local/lib/python3.12/site-packages/airflow/models/taskinstance.py", line 274, in _run_raw_task
    TaskInstance._execute_task_with_callbacks(
  File "/home/airflow/.local/lib/python3.12/site-packages/airflow/models/taskinstance.py", line 3161, in _execute_task_with_callbacks
    result = self._execute_task(context, task_orig)
  File "/home/airflow/.local/lib/python3.12/site-packages/airflow/models/taskinstance.py", line 3185, in _execute_task
    return _execute_task(self, context, task_orig)
  File "/home/airflow/.local/lib/python3.12/site-packages/airflow/models/taskinstance.py", line 768, in _execute_task
    result = _execute_callable(context=context, **execute_callable_kwargs)
  File "/home/airflow/.local/lib/python3.12/site-packages/airflow/models/taskinstance.py", line 734, in _execute_callable
    return ExecutionCallableRunner(
  File "/home/airflow/.local/lib/python3.12/site-packages/airflow/utils/operator_helpers.py", line 252, in run
    return self.func(*args, **kwargs)
  File "/home/airflow/.local/lib/python3.12/site-packages/airflow/models/baseoperator.py", line 424, in wrapper
    return func(self, *args, **kwargs)
  File "/home/airflow/.local/lib/python3.12/site-packages/airflow/operators/trigger_dagrun.py", line 263, in execute
    time.sleep(self.poke_interval)
  File "/home/airflow/.local/lib/python3.12/site-packages/airflow/models/taskinstance.py", line 3095, in signal_handler
    self.log.error("Stacktrace: \n%s", "".join(traceback.format_stack()))

[2025-04-19T15:20:11.339+0000] {taskinstance.py:3313} ERROR - Task failed with exception
Traceback (most recent call last):
  File "/home/airflow/.local/lib/python3.12/site-packages/airflow/models/taskinstance.py", line 768, in _execute_task
    result = _execute_callable(context=context, **execute_callable_kwargs)
             ^^^^^^^^^^^^^^^^^^^^^^^^^^^^^^^^^^^^^^^^^^^^^^^^^^^^^^^^^^^^^
  File "/home/airflow/.local/lib/python3.12/site-packages/airflow/models/taskinstance.py", line 734, in _execute_callable
    return ExecutionCallableRunner(
           ^^^^^^^^^^^^^^^^^^^^^^^^
  File "/home/airflow/.local/lib/python3.12/site-packages/airflow/utils/operator_helpers.py", line 252, in run
    return self.func(*args, **kwargs)
           ^^^^^^^^^^^^^^^^^^^^^^^^^^
  File "/home/airflow/.local/lib/python3.12/site-packages/airflow/models/baseoperator.py", line 424, in wrapper
    return func(self, *args, **kwargs)
           ^^^^^^^^^^^^^^^^^^^^^^^^^^^
  File "/home/airflow/.local/lib/python3.12/site-packages/airflow/operators/trigger_dagrun.py", line 263, in execute
    time.sleep(self.poke_interval)
  File "/home/airflow/.local/lib/python3.12/site-packages/airflow/models/taskinstance.py", line 3097, in signal_handler
    raise AirflowTaskTerminated("Task received SIGTERM signal")
airflow.exceptions.AirflowTaskTerminated: Task received SIGTERM signal
[2025-04-19T15:20:11.343+0000] {taskinstance.py:1226} INFO - Marking task as FAILED. dag_id=load_new_orders, task_id=dbt_test, run_id=manual__2025-04-19T15:19:04.998325+00:00, execution_date=20250419T151904, start_date=20250419T151955, end_date=20250419T152011
[2025-04-19T15:20:11.351+0000] {taskinstance.py:341} INFO - ::group::Post task execution logs
[2025-04-19T15:20:11.351+0000] {standard_task_runner.py:124} ERROR - Failed to execute job 215 for task dbt_test ((psycopg2.errors.ForeignKeyViolation) insert or update on table "task_fail" violates foreign key constraint "task_fail_ti_fkey"
DETAIL:  Key (dag_id, task_id, run_id, map_index)=(load_new_orders, dbt_test, manual__2025-04-19T15:19:04.998325+00:00, -1) is not present in table "task_instance".

[SQL: INSERT INTO task_fail (task_id, dag_id, run_id, map_index, start_date, end_date, duration) VALUES (%(task_id)s, %(dag_id)s, %(run_id)s, %(map_index)s, %(start_date)s, %(end_date)s, %(duration)s) RETURNING task_fail.id]
[parameters: {'task_id': 'dbt_test', 'dag_id': 'load_new_orders', 'run_id': 'manual__2025-04-19T15:19:04.998325+00:00', 'map_index': -1, 'start_date': datetime.datetime(2025, 4, 19, 15, 19, 55, 833269, tzinfo=Timezone('UTC')), 'end_date': datetime.datetime(2025, 4, 19, 15, 20, 11, 343076, tzinfo=Timezone('UTC')), 'duration': 15}]
(Background on this error at: https://sqlalche.me/e/14/gkpj); 2127)
Traceback (most recent call last):
  File "/home/airflow/.local/lib/python3.12/site-packages/airflow/models/taskinstance.py", line 274, in _run_raw_task
    TaskInstance._execute_task_with_callbacks(
  File "/home/airflow/.local/lib/python3.12/site-packages/airflow/models/taskinstance.py", line 3161, in _execute_task_with_callbacks
    result = self._execute_task(context, task_orig)
             ^^^^^^^^^^^^^^^^^^^^^^^^^^^^^^^^^^^^^^
  File "/home/airflow/.local/lib/python3.12/site-packages/airflow/models/taskinstance.py", line 3185, in _execute_task
    return _execute_task(self, context, task_orig)
           ^^^^^^^^^^^^^^^^^^^^^^^^^^^^^^^^^^^^^^^
  File "/home/airflow/.local/lib/python3.12/site-packages/airflow/models/taskinstance.py", line 768, in _execute_task
    result = _execute_callable(context=context, **execute_callable_kwargs)
             ^^^^^^^^^^^^^^^^^^^^^^^^^^^^^^^^^^^^^^^^^^^^^^^^^^^^^^^^^^^^^
  File "/home/airflow/.local/lib/python3.12/site-packages/airflow/models/taskinstance.py", line 734, in _execute_callable
    return ExecutionCallableRunner(
           ^^^^^^^^^^^^^^^^^^^^^^^^
  File "/home/airflow/.local/lib/python3.12/site-packages/airflow/utils/operator_helpers.py", line 252, in run
    return self.func(*args, **kwargs)
           ^^^^^^^^^^^^^^^^^^^^^^^^^^
  File "/home/airflow/.local/lib/python3.12/site-packages/airflow/models/baseoperator.py", line 424, in wrapper
    return func(self, *args, **kwargs)
           ^^^^^^^^^^^^^^^^^^^^^^^^^^^
  File "/home/airflow/.local/lib/python3.12/site-packages/airflow/operators/trigger_dagrun.py", line 263, in execute
    time.sleep(self.poke_interval)
  File "/home/airflow/.local/lib/python3.12/site-packages/airflow/models/taskinstance.py", line 3097, in signal_handler
    raise AirflowTaskTerminated("Task received SIGTERM signal")
airflow.exceptions.AirflowTaskTerminated: Task received SIGTERM signal

During handling of the above exception, another exception occurred:

Traceback (most recent call last):
  File "/home/airflow/.local/lib/python3.12/site-packages/sqlalchemy/engine/base.py", line 1910, in _execute_context
    self.dialect.do_execute(
  File "/home/airflow/.local/lib/python3.12/site-packages/sqlalchemy/engine/default.py", line 736, in do_execute
    cursor.execute(statement, parameters)
psycopg2.errors.ForeignKeyViolation: insert or update on table "task_fail" violates foreign key constraint "task_fail_ti_fkey"
DETAIL:  Key (dag_id, task_id, run_id, map_index)=(load_new_orders, dbt_test, manual__2025-04-19T15:19:04.998325+00:00, -1) is not present in table "task_instance".


The above exception was the direct cause of the following exception:

Traceback (most recent call last):
  File "/home/airflow/.local/lib/python3.12/site-packages/airflow/task/task_runner/standard_task_runner.py", line 117, in _start_by_fork
    ret = args.func(args, dag=self.dag)
          ^^^^^^^^^^^^^^^^^^^^^^^^^^^^^
  File "/home/airflow/.local/lib/python3.12/site-packages/airflow/cli/cli_config.py", line 49, in command
    return func(*args, **kwargs)
           ^^^^^^^^^^^^^^^^^^^^^
  File "/home/airflow/.local/lib/python3.12/site-packages/airflow/utils/cli.py", line 116, in wrapper
    return f(*args, **kwargs)
           ^^^^^^^^^^^^^^^^^^
  File "/home/airflow/.local/lib/python3.12/site-packages/airflow/cli/commands/task_command.py", line 483, in task_run
    task_return_code = _run_task_by_selected_method(args, _dag, ti)
                       ^^^^^^^^^^^^^^^^^^^^^^^^^^^^^^^^^^^^^^^^^^^^
  File "/home/airflow/.local/lib/python3.12/site-packages/airflow/cli/commands/task_command.py", line 256, in _run_task_by_selected_method
    return _run_raw_task(args, ti)
           ^^^^^^^^^^^^^^^^^^^^^^^
  File "/home/airflow/.local/lib/python3.12/site-packages/airflow/cli/commands/task_command.py", line 341, in _run_raw_task
    return ti._run_raw_task(
           ^^^^^^^^^^^^^^^^^
  File "/home/airflow/.local/lib/python3.12/site-packages/airflow/utils/session.py", line 97, in wrapper
    return func(*args, session=session, **kwargs)
           ^^^^^^^^^^^^^^^^^^^^^^^^^^^^^^^^^^^^^^
  File "/home/airflow/.local/lib/python3.12/site-packages/airflow/models/taskinstance.py", line 3006, in _run_raw_task
    return _run_raw_task(
           ^^^^^^^^^^^^^^
  File "/home/airflow/.local/lib/python3.12/site-packages/airflow/models/taskinstance.py", line 328, in _run_raw_task
    ti.handle_failure(e, test_mode, context, session=session)
  File "/home/airflow/.local/lib/python3.12/site-packages/airflow/utils/session.py", line 94, in wrapper
    return func(*args, **kwargs)
           ^^^^^^^^^^^^^^^^^^^^^
  File "/home/airflow/.local/lib/python3.12/site-packages/airflow/models/taskinstance.py", line 3434, in handle_failure
    _handle_failure(
  File "/home/airflow/.local/lib/python3.12/site-packages/airflow/utils/session.py", line 94, in wrapper
    return func(*args, **kwargs)
           ^^^^^^^^^^^^^^^^^^^^^
  File "/home/airflow/.local/lib/python3.12/site-packages/airflow/api_internal/internal_api_call.py", line 166, in wrapper
    return func(*args, **kwargs)
           ^^^^^^^^^^^^^^^^^^^^^
  File "/home/airflow/.local/lib/python3.12/site-packages/airflow/models/taskinstance.py", line 1244, in _handle_failure
    TaskInstance.save_to_db(task_instance, session)
  File "/home/airflow/.local/lib/python3.12/site-packages/airflow/api_internal/internal_api_call.py", line 166, in wrapper
    return func(*args, **kwargs)
           ^^^^^^^^^^^^^^^^^^^^^
  File "/home/airflow/.local/lib/python3.12/site-packages/airflow/utils/session.py", line 94, in wrapper
    return func(*args, **kwargs)
           ^^^^^^^^^^^^^^^^^^^^^
  File "/home/airflow/.local/lib/python3.12/site-packages/airflow/models/taskinstance.py", line 3402, in save_to_db
    ti.get_dagrun().refresh_from_db()
    ^^^^^^^^^^^^^^^
  File "/home/airflow/.local/lib/python3.12/site-packages/airflow/utils/session.py", line 96, in wrapper
    with create_session() as session:
         ^^^^^^^^^^^^^^^^
  File "/usr/local/lib/python3.12/contextlib.py", line 144, in __exit__
    next(self.gen)
  File "/home/airflow/.local/lib/python3.12/site-packages/airflow/utils/session.py", line 57, in create_session
    session.commit()
  File "/home/airflow/.local/lib/python3.12/site-packages/sqlalchemy/orm/session.py", line 1454, in commit
    self._transaction.commit(_to_root=self.future)
  File "/home/airflow/.local/lib/python3.12/site-packages/sqlalchemy/orm/session.py", line 832, in commit
    self._prepare_impl()
  File "/home/airflow/.local/lib/python3.12/site-packages/sqlalchemy/orm/session.py", line 811, in _prepare_impl
    self.session.flush()
  File "/home/airflow/.local/lib/python3.12/site-packages/sqlalchemy/orm/session.py", line 3449, in flush
    self._flush(objects)
  File "/home/airflow/.local/lib/python3.12/site-packages/sqlalchemy/orm/session.py", line 3588, in _flush
    with util.safe_reraise():
         ^^^^^^^^^^^^^^^^^^^
  File "/home/airflow/.local/lib/python3.12/site-packages/sqlalchemy/util/langhelpers.py", line 70, in __exit__
    compat.raise_(
  File "/home/airflow/.local/lib/python3.12/site-packages/sqlalchemy/util/compat.py", line 211, in raise_
    raise exception
  File "/home/airflow/.local/lib/python3.12/site-packages/sqlalchemy/orm/session.py", line 3549, in _flush
    flush_context.execute()
  File "/home/airflow/.local/lib/python3.12/site-packages/sqlalchemy/orm/unitofwork.py", line 456, in execute
    rec.execute(self)
  File "/home/airflow/.local/lib/python3.12/site-packages/sqlalchemy/orm/unitofwork.py", line 630, in execute
    util.preloaded.orm_persistence.save_obj(
  File "/home/airflow/.local/lib/python3.12/site-packages/sqlalchemy/orm/persistence.py", line 245, in save_obj
    _emit_insert_statements(
  File "/home/airflow/.local/lib/python3.12/site-packages/sqlalchemy/orm/persistence.py", line 1238, in _emit_insert_statements
    result = connection._execute_20(
             ^^^^^^^^^^^^^^^^^^^^^^^
  File "/home/airflow/.local/lib/python3.12/site-packages/sqlalchemy/engine/base.py", line 1710, in _execute_20
    return meth(self, args_10style, kwargs_10style, execution_options)
           ^^^^^^^^^^^^^^^^^^^^^^^^^^^^^^^^^^^^^^^^^^^^^^^^^^^^^^^^^^^
  File "/home/airflow/.local/lib/python3.12/site-packages/sqlalchemy/sql/elements.py", line 334, in _execute_on_connection
    return connection._execute_clauseelement(
           ^^^^^^^^^^^^^^^^^^^^^^^^^^^^^^^^^^
  File "/home/airflow/.local/lib/python3.12/site-packages/sqlalchemy/engine/base.py", line 1577, in _execute_clauseelement
    ret = self._execute_context(
          ^^^^^^^^^^^^^^^^^^^^^^
  File "/home/airflow/.local/lib/python3.12/site-packages/sqlalchemy/engine/base.py", line 1953, in _execute_context
    self._handle_dbapi_exception(
  File "/home/airflow/.local/lib/python3.12/site-packages/sqlalchemy/engine/base.py", line 2134, in _handle_dbapi_exception
    util.raise_(
  File "/home/airflow/.local/lib/python3.12/site-packages/sqlalchemy/util/compat.py", line 211, in raise_
    raise exception
  File "/home/airflow/.local/lib/python3.12/site-packages/sqlalchemy/engine/base.py", line 1910, in _execute_context
    self.dialect.do_execute(
  File "/home/airflow/.local/lib/python3.12/site-packages/sqlalchemy/engine/default.py", line 736, in do_execute
    cursor.execute(statement, parameters)
sqlalchemy.exc.IntegrityError: (psycopg2.errors.ForeignKeyViolation) insert or update on table "task_fail" violates foreign key constraint "task_fail_ti_fkey"
DETAIL:  Key (dag_id, task_id, run_id, map_index)=(load_new_orders, dbt_test, manual__2025-04-19T15:19:04.998325+00:00, -1) is not present in table "task_instance".

[SQL: INSERT INTO task_fail (task_id, dag_id, run_id, map_index, start_date, end_date, duration) VALUES (%(task_id)s, %(dag_id)s, %(run_id)s, %(map_index)s, %(start_date)s, %(end_date)s, %(duration)s) RETURNING task_fail.id]
[parameters: {'task_id': 'dbt_test', 'dag_id': 'load_new_orders', 'run_id': 'manual__2025-04-19T15:19:04.998325+00:00', 'map_index': -1, 'start_date': datetime.datetime(2025, 4, 19, 15, 19, 55, 833269, tzinfo=Timezone('UTC')), 'end_date': datetime.datetime(2025, 4, 19, 15, 20, 11, 343076, tzinfo=Timezone('UTC')), 'duration': 15}]
(Background on this error at: https://sqlalche.me/e/14/gkpj)
[2025-04-19T15:20:11.380+0000] {process_utils.py:80} INFO - Process psutil.Process(pid=2127, status='terminated', exitcode=1, started='15:19:55') (2127) terminated with exit code 1
