[2025-04-19T15:15:03.069+0000] {local_task_job_runner.py:123} INFO - ::group::Pre task execution logs
[2025-04-19T15:15:03.197+0000] {taskinstance.py:2614} INFO - Dependencies all met for dep_context=non-requeueable deps ti=<TaskInstance: dbt_etl_pipeline_mart.dbt_marts_core scheduled__2025-04-19T15:15:00.699854+00:00 [queued]>
[2025-04-19T15:15:03.227+0000] {taskinstance.py:2614} INFO - Dependencies all met for dep_context=requeueable deps ti=<TaskInstance: dbt_etl_pipeline_mart.dbt_marts_core scheduled__2025-04-19T15:15:00.699854+00:00 [queued]>
[2025-04-19T15:15:03.227+0000] {taskinstance.py:2867} INFO - Starting attempt 1 of 1
[2025-04-19T15:15:03.258+0000] {taskinstance.py:2890} INFO - Executing <Task(BashOperator): dbt_marts_core> on 2025-04-19 15:15:00.699854+00:00
[2025-04-19T15:15:03.295+0000] {logging_mixin.py:190} WARNING - /home/airflow/.local/lib/python3.12/site-packages/airflow/task/task_runner/standard_task_runner.py:70 DeprecationWarning: This process (pid=1503) is multi-threaded, use of fork() may lead to deadlocks in the child.
[2025-04-19T15:15:03.304+0000] {standard_task_runner.py:72} INFO - Started process 1504 to run task
[2025-04-19T15:15:03.295+0000] {standard_task_runner.py:104} INFO - Running: ['airflow', 'tasks', 'run', 'dbt_etl_pipeline_mart', 'dbt_marts_core', 'scheduled__2025-04-19T15:15:00.699854+00:00', '--job-id', '199', '--raw', '--subdir', 'DAGS_FOLDER/dbt_marts.py', '--cfg-path', '/tmp/tmpkroswg40']
[2025-04-19T15:15:03.307+0000] {standard_task_runner.py:105} INFO - Job 199: Subtask dbt_marts_core
[2025-04-19T15:15:03.727+0000] {task_command.py:467} INFO - Running <TaskInstance: dbt_etl_pipeline_mart.dbt_marts_core scheduled__2025-04-19T15:15:00.699854+00:00 [running]> on host 27536697ee14
[2025-04-19T15:15:04.273+0000] {taskinstance.py:3134} INFO - Exporting env vars: AIRFLOW_CTX_DAG_OWNER='azizjon' AIRFLOW_CTX_DAG_ID='dbt_etl_pipeline_mart' AIRFLOW_CTX_TASK_ID='dbt_marts_core' AIRFLOW_CTX_EXECUTION_DATE='2025-04-19T15:15:00.699854+00:00' AIRFLOW_CTX_TRY_NUMBER='1' AIRFLOW_CTX_DAG_RUN_ID='scheduled__2025-04-19T15:15:00.699854+00:00'
[2025-04-19T15:15:04.277+0000] {taskinstance.py:732} INFO - ::endgroup::
[2025-04-19T15:15:04.328+0000] {subprocess.py:78} INFO - Tmp dir root location: /tmp
[2025-04-19T15:15:04.333+0000] {subprocess.py:88} INFO - Running command: ['/usr/bin/bash', '-c', '\n        export PATH=/home/airflow/.local/bin:$PATH\n        cd /opt/airflow/commerce_dbt\n        dbt run --select marts.core --profiles-dir .\n        ']
[2025-04-19T15:15:04.357+0000] {subprocess.py:99} INFO - Output:
[2025-04-19T15:15:08.724+0000] {subprocess.py:106} INFO - [0m15:15:08  Running with dbt=1.7.0
[2025-04-19T15:15:08.974+0000] {subprocess.py:106} INFO - [0m15:15:08  Registered adapter: postgres=1.7.0
[2025-04-19T15:15:09.428+0000] {subprocess.py:106} INFO - [0m15:15:09  [[33mWARNING[0m]: Configuration paths exist in your dbt_project.yml file which do not apply to any resources.
[2025-04-19T15:15:09.428+0000] {subprocess.py:106} INFO - There are 1 unused configuration paths:
[2025-04-19T15:15:09.429+0000] {subprocess.py:106} INFO - - seeds.initial_dataset
[2025-04-19T15:15:09.490+0000] {subprocess.py:106} INFO - [0m15:15:09  Found 13 models, 1 snapshot, 6 seeds, 43 tests, 6 sources, 0 exposures, 0 metrics, 401 macros, 0 groups, 0 semantic models
[2025-04-19T15:15:09.493+0000] {subprocess.py:106} INFO - [0m15:15:09
[2025-04-19T15:15:09.921+0000] {subprocess.py:106} INFO - [0m15:15:09  Concurrency: 4 threads (target='dev')
[2025-04-19T15:15:09.922+0000] {subprocess.py:106} INFO - [0m15:15:09
[2025-04-19T15:15:09.939+0000] {subprocess.py:106} INFO - [0m15:15:09  1 of 5 START sql table model commerce_core.dim_customers ....................... [RUN]
[2025-04-19T15:15:09.940+0000] {subprocess.py:106} INFO - [0m15:15:09  2 of 5 START sql table model commerce_core.dim_products ........................ [RUN]
[2025-04-19T15:15:09.941+0000] {subprocess.py:106} INFO - [0m15:15:09  3 of 5 START sql table model commerce_core.dim_stores .......................... [RUN]
[2025-04-19T15:15:10.194+0000] {subprocess.py:106} INFO - [0m15:15:10  1 of 5 ERROR creating sql table model commerce_core.dim_customers .............. [[31mERROR[0m in 0.25s]
[2025-04-19T15:15:10.195+0000] {subprocess.py:106} INFO - [0m15:15:10  3 of 5 ERROR creating sql table model commerce_core.dim_stores ................. [[31mERROR[0m in 0.25s]
[2025-04-19T15:15:10.196+0000] {subprocess.py:106} INFO - [0m15:15:10  2 of 5 ERROR creating sql table model commerce_core.dim_products ............... [[31mERROR[0m in 0.25s]
[2025-04-19T15:15:10.206+0000] {subprocess.py:106} INFO - [0m15:15:10  4 of 5 SKIP relation commerce_core.fct_orders .................................. [[33mSKIP[0m]
[2025-04-19T15:15:10.206+0000] {subprocess.py:106} INFO - [0m15:15:10  5 of 5 SKIP relation commerce_core.ml_analytics ................................ [[33mSKIP[0m]
[2025-04-19T15:15:10.271+0000] {subprocess.py:106} INFO - [0m15:15:10
[2025-04-19T15:15:10.272+0000] {subprocess.py:106} INFO - [0m15:15:10  Finished running 5 table models in 0 hours 0 minutes and 0.78 seconds (0.78s).
[2025-04-19T15:15:10.328+0000] {subprocess.py:106} INFO - [0m15:15:10
[2025-04-19T15:15:10.329+0000] {subprocess.py:106} INFO - [0m15:15:10  [31mCompleted with 3 errors and 0 warnings:[0m
[2025-04-19T15:15:10.331+0000] {subprocess.py:106} INFO - [0m15:15:10
[2025-04-19T15:15:10.332+0000] {subprocess.py:106} INFO - [0m15:15:10    Database Error in model dim_customers (models/marts/core/dim_customers.sql)
[2025-04-19T15:15:10.332+0000] {subprocess.py:106} INFO -   relation "commerce_staging.stg_customers" does not exist
[2025-04-19T15:15:10.333+0000] {subprocess.py:106} INFO -   LINE 13:     select * from "postgres"."commerce_staging"."stg_custome...
[2025-04-19T15:15:10.334+0000] {subprocess.py:106} INFO -                              ^
[2025-04-19T15:15:10.334+0000] {subprocess.py:106} INFO -   compiled Code at target/run/commerce_dbt/models/marts/core/dim_customers.sql
[2025-04-19T15:15:10.335+0000] {subprocess.py:106} INFO - [0m15:15:10
[2025-04-19T15:15:10.336+0000] {subprocess.py:106} INFO - [0m15:15:10    Database Error in model dim_stores (models/marts/core/dim_stores.sql)
[2025-04-19T15:15:10.336+0000] {subprocess.py:106} INFO -   relation "commerce_staging.stg_stores" does not exist
[2025-04-19T15:15:10.337+0000] {subprocess.py:106} INFO -   LINE 13:     select * from "postgres"."commerce_staging"."stg_stores"
[2025-04-19T15:15:10.337+0000] {subprocess.py:106} INFO -                              ^
[2025-04-19T15:15:10.338+0000] {subprocess.py:106} INFO -   compiled Code at target/run/commerce_dbt/models/marts/core/dim_stores.sql
[2025-04-19T15:15:10.338+0000] {subprocess.py:106} INFO - [0m15:15:10
[2025-04-19T15:15:10.339+0000] {subprocess.py:106} INFO - [0m15:15:10    Database Error in model dim_products (models/marts/core/dim_products.sql)
[2025-04-19T15:15:10.339+0000] {subprocess.py:106} INFO -   relation "commerce_staging.stg_products" does not exist
[2025-04-19T15:15:10.340+0000] {subprocess.py:106} INFO -   LINE 13:     select * from "postgres"."commerce_staging"."stg_product...
[2025-04-19T15:15:10.341+0000] {subprocess.py:106} INFO -                              ^
[2025-04-19T15:15:10.341+0000] {subprocess.py:106} INFO -   compiled Code at target/run/commerce_dbt/models/marts/core/dim_products.sql
[2025-04-19T15:15:10.341+0000] {subprocess.py:106} INFO - [0m15:15:10
[2025-04-19T15:15:10.342+0000] {subprocess.py:106} INFO - [0m15:15:10  Done. PASS=0 WARN=0 ERROR=3 SKIP=2 TOTAL=5
[2025-04-19T15:15:11.489+0000] {subprocess.py:110} INFO - Command exited with return code 1
[2025-04-19T15:15:11.666+0000] {taskinstance.py:3313} ERROR - Task failed with exception
Traceback (most recent call last):
  File "/home/airflow/.local/lib/python3.12/site-packages/airflow/models/taskinstance.py", line 768, in _execute_task
    result = _execute_callable(context=context, **execute_callable_kwargs)
             ^^^^^^^^^^^^^^^^^^^^^^^^^^^^^^^^^^^^^^^^^^^^^^^^^^^^^^^^^^^^^
  File "/home/airflow/.local/lib/python3.12/site-packages/airflow/models/taskinstance.py", line 734, in _execute_callable
    return ExecutionCallableRunner(
           ^^^^^^^^^^^^^^^^^^^^^^^^
  File "/home/airflow/.local/lib/python3.12/site-packages/airflow/utils/operator_helpers.py", line 252, in run
    return self.func(*args, **kwargs)
           ^^^^^^^^^^^^^^^^^^^^^^^^^^
  File "/home/airflow/.local/lib/python3.12/site-packages/airflow/models/baseoperator.py", line 424, in wrapper
    return func(self, *args, **kwargs)
           ^^^^^^^^^^^^^^^^^^^^^^^^^^^
  File "/home/airflow/.local/lib/python3.12/site-packages/airflow/operators/bash.py", line 276, in execute
    raise AirflowException(
airflow.exceptions.AirflowException: Bash command failed. The command returned a non-zero exit code 1.
[2025-04-19T15:15:11.677+0000] {taskinstance.py:1226} INFO - Marking task as FAILED. dag_id=dbt_etl_pipeline_mart, task_id=dbt_marts_core, run_id=scheduled__2025-04-19T15:15:00.699854+00:00, execution_date=20250419T151500, start_date=20250419T151503, end_date=20250419T151511
[2025-04-19T15:15:11.814+0000] {taskinstance.py:341} INFO - ::group::Post task execution logs
[2025-04-19T15:15:11.815+0000] {standard_task_runner.py:124} ERROR - Failed to execute job 199 for task dbt_marts_core (Bash command failed. The command returned a non-zero exit code 1.; 1504)
Traceback (most recent call last):
  File "/home/airflow/.local/lib/python3.12/site-packages/airflow/task/task_runner/standard_task_runner.py", line 117, in _start_by_fork
    ret = args.func(args, dag=self.dag)
          ^^^^^^^^^^^^^^^^^^^^^^^^^^^^^
  File "/home/airflow/.local/lib/python3.12/site-packages/airflow/cli/cli_config.py", line 49, in command
    return func(*args, **kwargs)
           ^^^^^^^^^^^^^^^^^^^^^
  File "/home/airflow/.local/lib/python3.12/site-packages/airflow/utils/cli.py", line 116, in wrapper
    return f(*args, **kwargs)
           ^^^^^^^^^^^^^^^^^^
  File "/home/airflow/.local/lib/python3.12/site-packages/airflow/cli/commands/task_command.py", line 483, in task_run
    task_return_code = _run_task_by_selected_method(args, _dag, ti)
                       ^^^^^^^^^^^^^^^^^^^^^^^^^^^^^^^^^^^^^^^^^^^^
  File "/home/airflow/.local/lib/python3.12/site-packages/airflow/cli/commands/task_command.py", line 256, in _run_task_by_selected_method
    return _run_raw_task(args, ti)
           ^^^^^^^^^^^^^^^^^^^^^^^
  File "/home/airflow/.local/lib/python3.12/site-packages/airflow/cli/commands/task_command.py", line 341, in _run_raw_task
    return ti._run_raw_task(
           ^^^^^^^^^^^^^^^^^
  File "/home/airflow/.local/lib/python3.12/site-packages/airflow/utils/session.py", line 97, in wrapper
    return func(*args, session=session, **kwargs)
           ^^^^^^^^^^^^^^^^^^^^^^^^^^^^^^^^^^^^^^
  File "/home/airflow/.local/lib/python3.12/site-packages/airflow/models/taskinstance.py", line 3006, in _run_raw_task
    return _run_raw_task(
           ^^^^^^^^^^^^^^
  File "/home/airflow/.local/lib/python3.12/site-packages/airflow/models/taskinstance.py", line 274, in _run_raw_task
    TaskInstance._execute_task_with_callbacks(
  File "/home/airflow/.local/lib/python3.12/site-packages/airflow/models/taskinstance.py", line 3161, in _execute_task_with_callbacks
    result = self._execute_task(context, task_orig)
             ^^^^^^^^^^^^^^^^^^^^^^^^^^^^^^^^^^^^^^
  File "/home/airflow/.local/lib/python3.12/site-packages/airflow/models/taskinstance.py", line 3185, in _execute_task
    return _execute_task(self, context, task_orig)
           ^^^^^^^^^^^^^^^^^^^^^^^^^^^^^^^^^^^^^^^
  File "/home/airflow/.local/lib/python3.12/site-packages/airflow/models/taskinstance.py", line 768, in _execute_task
    result = _execute_callable(context=context, **execute_callable_kwargs)
             ^^^^^^^^^^^^^^^^^^^^^^^^^^^^^^^^^^^^^^^^^^^^^^^^^^^^^^^^^^^^^
  File "/home/airflow/.local/lib/python3.12/site-packages/airflow/models/taskinstance.py", line 734, in _execute_callable
    return ExecutionCallableRunner(
           ^^^^^^^^^^^^^^^^^^^^^^^^
  File "/home/airflow/.local/lib/python3.12/site-packages/airflow/utils/operator_helpers.py", line 252, in run
    return self.func(*args, **kwargs)
           ^^^^^^^^^^^^^^^^^^^^^^^^^^
  File "/home/airflow/.local/lib/python3.12/site-packages/airflow/models/baseoperator.py", line 424, in wrapper
    return func(self, *args, **kwargs)
           ^^^^^^^^^^^^^^^^^^^^^^^^^^^
  File "/home/airflow/.local/lib/python3.12/site-packages/airflow/operators/bash.py", line 276, in execute
    raise AirflowException(
airflow.exceptions.AirflowException: Bash command failed. The command returned a non-zero exit code 1.
[2025-04-19T15:15:11.849+0000] {local_task_job_runner.py:266} INFO - Task exited with return code 1
[2025-04-19T15:15:11.926+0000] {taskinstance.py:3901} INFO - 0 downstream tasks scheduled from follow-on schedule check
[2025-04-19T15:15:11.933+0000] {local_task_job_runner.py:245} INFO - ::endgroup::
