[2025-04-19T15:47:55.250+0000] {local_task_job_runner.py:123} INFO - ::group::Pre task execution logs
[2025-04-19T15:47:55.310+0000] {taskinstance.py:2614} INFO - Dependencies all met for dep_context=non-requeueable deps ti=<TaskInstance: load_new_orders.store_to_sql_order_items scheduled__2025-04-19T14:00:00+00:00 [queued]>
[2025-04-19T15:47:55.324+0000] {taskinstance.py:2614} INFO - Dependencies all met for dep_context=requeueable deps ti=<TaskInstance: load_new_orders.store_to_sql_order_items scheduled__2025-04-19T14:00:00+00:00 [queued]>
[2025-04-19T15:47:55.327+0000] {taskinstance.py:2867} INFO - Starting attempt 1 of 1
[2025-04-19T15:47:55.341+0000] {taskinstance.py:2890} INFO - Executing <Task(TriggerDagRunOperator): store_to_sql_order_items> on 2025-04-19 14:00:00+00:00
[2025-04-19T15:47:55.348+0000] {logging_mixin.py:190} WARNING - /home/airflow/.local/lib/python3.12/site-packages/airflow/task/task_runner/standard_task_runner.py:70 DeprecationWarning: This process (pid=4648) is multi-threaded, use of fork() may lead to deadlocks in the child.
[2025-04-19T15:47:55.349+0000] {standard_task_runner.py:72} INFO - Started process 4649 to run task
[2025-04-19T15:47:55.349+0000] {standard_task_runner.py:104} INFO - Running: ['airflow', 'tasks', 'run', 'load_new_orders', 'store_to_sql_order_items', 'scheduled__2025-04-19T14:00:00+00:00', '--job-id', '235', '--raw', '--subdir', 'DAGS_FOLDER/store_to_sql_orders.py', '--cfg-path', '/tmp/tmpab46zkq6']
[2025-04-19T15:47:55.350+0000] {standard_task_runner.py:105} INFO - Job 235: Subtask store_to_sql_order_items
[2025-04-19T15:47:55.515+0000] {task_command.py:467} INFO - Running <TaskInstance: load_new_orders.store_to_sql_order_items scheduled__2025-04-19T14:00:00+00:00 [running]> on host 27536697ee14
[2025-04-19T15:47:55.718+0000] {taskinstance.py:3134} INFO - Exporting env vars: AIRFLOW_CTX_DAG_OWNER='azizjon' AIRFLOW_CTX_DAG_ID='load_new_orders' AIRFLOW_CTX_TASK_ID='store_to_sql_order_items' AIRFLOW_CTX_EXECUTION_DATE='2025-04-19T14:00:00+00:00' AIRFLOW_CTX_TRY_NUMBER='1' AIRFLOW_CTX_DAG_RUN_ID='scheduled__2025-04-19T14:00:00+00:00'
[2025-04-19T15:47:55.719+0000] {taskinstance.py:732} INFO - ::endgroup::
[2025-04-19T15:47:56.914+0000] {trigger_dagrun.py:257} INFO - Waiting for load_new_order_items on 2025-04-19 14:00:00+00:00 to become allowed state ['success'] ...
[2025-04-19T15:48:01.966+0000] {trigger_dagrun.py:271} INFO - load_new_order_items finished with allowed state success
[2025-04-19T15:48:02.018+0000] {taskinstance.py:341} INFO - ::group::Post task execution logs
[2025-04-19T15:48:02.019+0000] {taskinstance.py:353} INFO - Marking task as SUCCESS. dag_id=load_new_orders, task_id=store_to_sql_order_items, run_id=scheduled__2025-04-19T14:00:00+00:00, execution_date=20250419T140000, start_date=20250419T154755, end_date=20250419T154802
[2025-04-19T15:48:02.091+0000] {standard_task_runner.py:124} ERROR - Failed to execute job 235 for task store_to_sql_order_items (No row was found when one was required; 4649)
Traceback (most recent call last):
  File "/home/airflow/.local/lib/python3.12/site-packages/airflow/task/task_runner/standard_task_runner.py", line 117, in _start_by_fork
    ret = args.func(args, dag=self.dag)
          ^^^^^^^^^^^^^^^^^^^^^^^^^^^^^
  File "/home/airflow/.local/lib/python3.12/site-packages/airflow/cli/cli_config.py", line 49, in command
    return func(*args, **kwargs)
           ^^^^^^^^^^^^^^^^^^^^^
  File "/home/airflow/.local/lib/python3.12/site-packages/airflow/utils/cli.py", line 116, in wrapper
    return f(*args, **kwargs)
           ^^^^^^^^^^^^^^^^^^
  File "/home/airflow/.local/lib/python3.12/site-packages/airflow/cli/commands/task_command.py", line 483, in task_run
    task_return_code = _run_task_by_selected_method(args, _dag, ti)
                       ^^^^^^^^^^^^^^^^^^^^^^^^^^^^^^^^^^^^^^^^^^^^
  File "/home/airflow/.local/lib/python3.12/site-packages/airflow/cli/commands/task_command.py", line 256, in _run_task_by_selected_method
    return _run_raw_task(args, ti)
           ^^^^^^^^^^^^^^^^^^^^^^^
  File "/home/airflow/.local/lib/python3.12/site-packages/airflow/cli/commands/task_command.py", line 341, in _run_raw_task
    return ti._run_raw_task(
           ^^^^^^^^^^^^^^^^^
  File "/home/airflow/.local/lib/python3.12/site-packages/airflow/utils/session.py", line 97, in wrapper
    return func(*args, session=session, **kwargs)
           ^^^^^^^^^^^^^^^^^^^^^^^^^^^^^^^^^^^^^^
  File "/home/airflow/.local/lib/python3.12/site-packages/airflow/models/taskinstance.py", line 3006, in _run_raw_task
    return _run_raw_task(
           ^^^^^^^^^^^^^^
  File "/home/airflow/.local/lib/python3.12/site-packages/airflow/models/taskinstance.py", line 366, in _run_raw_task
    TaskInstance.save_to_db(ti=ti, session=session)
  File "/home/airflow/.local/lib/python3.12/site-packages/airflow/api_internal/internal_api_call.py", line 166, in wrapper
    return func(*args, **kwargs)
           ^^^^^^^^^^^^^^^^^^^^^
  File "/home/airflow/.local/lib/python3.12/site-packages/airflow/utils/session.py", line 94, in wrapper
    return func(*args, **kwargs)
           ^^^^^^^^^^^^^^^^^^^^^
  File "/home/airflow/.local/lib/python3.12/site-packages/airflow/models/taskinstance.py", line 3402, in save_to_db
    ti.get_dagrun().refresh_from_db()
  File "/home/airflow/.local/lib/python3.12/site-packages/airflow/utils/session.py", line 97, in wrapper
    return func(*args, session=session, **kwargs)
           ^^^^^^^^^^^^^^^^^^^^^^^^^^^^^^^^^^^^^^
  File "/home/airflow/.local/lib/python3.12/site-packages/airflow/models/dagrun.py", line 361, in refresh_from_db
    ).one()
      ^^^^^
  File "/home/airflow/.local/lib/python3.12/site-packages/sqlalchemy/engine/result.py", line 1522, in one
    return self._only_one_row(
           ^^^^^^^^^^^^^^^^^^^
  File "/home/airflow/.local/lib/python3.12/site-packages/sqlalchemy/engine/result.py", line 562, in _only_one_row
    raise exc.NoResultFound(
sqlalchemy.exc.NoResultFound: No row was found when one was required
[2025-04-19T15:48:02.138+0000] {local_task_job_runner.py:266} INFO - Task exited with return code 1
[2025-04-19T15:48:02.187+0000] {local_task_job_runner.py:245} INFO - ::endgroup::
[2025-04-19T15:48:24.566+0000] {local_task_job_runner.py:123} INFO - ::group::Pre task execution logs
[2025-04-19T15:48:24.629+0000] {taskinstance.py:2614} INFO - Dependencies all met for dep_context=non-requeueable deps ti=<TaskInstance: load_new_orders.store_to_sql_order_items scheduled__2025-04-19T14:00:00+00:00 [queued]>
[2025-04-19T15:48:24.641+0000] {taskinstance.py:2614} INFO - Dependencies all met for dep_context=requeueable deps ti=<TaskInstance: load_new_orders.store_to_sql_order_items scheduled__2025-04-19T14:00:00+00:00 [queued]>
[2025-04-19T15:48:24.642+0000] {taskinstance.py:2867} INFO - Starting attempt 1 of 1
[2025-04-19T15:48:24.657+0000] {taskinstance.py:2890} INFO - Executing <Task(TriggerDagRunOperator): store_to_sql_order_items> on 2025-04-19 14:00:00+00:00
[2025-04-19T15:48:24.664+0000] {logging_mixin.py:190} WARNING - /home/airflow/.local/lib/python3.12/site-packages/airflow/task/task_runner/standard_task_runner.py:70 DeprecationWarning: This process (pid=4714) is multi-threaded, use of fork() may lead to deadlocks in the child.
[2025-04-19T15:48:24.664+0000] {standard_task_runner.py:104} INFO - Running: ['airflow', 'tasks', 'run', 'load_new_orders', 'store_to_sql_order_items', 'scheduled__2025-04-19T14:00:00+00:00', '--job-id', '238', '--raw', '--subdir', 'DAGS_FOLDER/store_to_sql_orders.py', '--cfg-path', '/tmp/tmpj_9u1f6j']
[2025-04-19T15:48:24.665+0000] {standard_task_runner.py:72} INFO - Started process 4715 to run task
[2025-04-19T15:48:24.665+0000] {standard_task_runner.py:105} INFO - Job 238: Subtask store_to_sql_order_items
[2025-04-19T15:48:24.845+0000] {task_command.py:467} INFO - Running <TaskInstance: load_new_orders.store_to_sql_order_items scheduled__2025-04-19T14:00:00+00:00 [running]> on host 27536697ee14
[2025-04-19T15:48:25.057+0000] {taskinstance.py:3134} INFO - Exporting env vars: AIRFLOW_CTX_DAG_OWNER='azizjon' AIRFLOW_CTX_DAG_ID='load_new_orders' AIRFLOW_CTX_TASK_ID='store_to_sql_order_items' AIRFLOW_CTX_EXECUTION_DATE='2025-04-19T14:00:00+00:00' AIRFLOW_CTX_TRY_NUMBER='1' AIRFLOW_CTX_DAG_RUN_ID='scheduled__2025-04-19T14:00:00+00:00'
[2025-04-19T15:48:25.059+0000] {taskinstance.py:732} INFO - ::endgroup::
[2025-04-19T15:48:26.534+0000] {trigger_dagrun.py:257} INFO - Waiting for load_new_order_items on 2025-04-19 14:00:00+00:00 to become allowed state ['success'] ...
[2025-04-19T15:48:31.587+0000] {trigger_dagrun.py:271} INFO - load_new_order_items finished with allowed state success
[2025-04-19T15:48:31.634+0000] {taskinstance.py:341} INFO - ::group::Post task execution logs
[2025-04-19T15:48:31.635+0000] {taskinstance.py:353} INFO - Marking task as SUCCESS. dag_id=load_new_orders, task_id=store_to_sql_order_items, run_id=scheduled__2025-04-19T14:00:00+00:00, execution_date=20250419T140000, start_date=20250419T154824, end_date=20250419T154831
[2025-04-19T15:48:31.802+0000] {local_task_job_runner.py:266} INFO - Task exited with return code 0
[2025-04-19T15:48:31.875+0000] {taskinstance.py:3901} INFO - 0 downstream tasks scheduled from follow-on schedule check
[2025-04-19T15:48:31.879+0000] {local_task_job_runner.py:245} INFO - ::endgroup::
[2025-04-19T15:57:25.928+0000] {local_task_job_runner.py:123} INFO - ::group::Pre task execution logs
[2025-04-19T15:57:25.999+0000] {taskinstance.py:2614} INFO - Dependencies all met for dep_context=non-requeueable deps ti=<TaskInstance: load_new_orders.store_to_sql_order_items scheduled__2025-04-19T14:00:00+00:00 [queued]>
[2025-04-19T15:57:26.012+0000] {taskinstance.py:2614} INFO - Dependencies all met for dep_context=requeueable deps ti=<TaskInstance: load_new_orders.store_to_sql_order_items scheduled__2025-04-19T14:00:00+00:00 [queued]>
[2025-04-19T15:57:26.013+0000] {taskinstance.py:2867} INFO - Starting attempt 1 of 1
[2025-04-19T15:57:26.030+0000] {taskinstance.py:2890} INFO - Executing <Task(TriggerDagRunOperator): store_to_sql_order_items> on 2025-04-19 14:00:00+00:00
[2025-04-19T15:57:26.037+0000] {logging_mixin.py:190} WARNING - /home/airflow/.local/lib/python3.12/site-packages/airflow/task/task_runner/standard_task_runner.py:70 DeprecationWarning: This process (pid=5555) is multi-threaded, use of fork() may lead to deadlocks in the child.
[2025-04-19T15:57:26.038+0000] {standard_task_runner.py:72} INFO - Started process 5556 to run task
[2025-04-19T15:57:26.038+0000] {standard_task_runner.py:104} INFO - Running: ['airflow', 'tasks', 'run', 'load_new_orders', 'store_to_sql_order_items', 'scheduled__2025-04-19T14:00:00+00:00', '--job-id', '250', '--raw', '--subdir', 'DAGS_FOLDER/store_to_sql_orders.py', '--cfg-path', '/tmp/tmp5f5tk4ed']
[2025-04-19T15:57:26.039+0000] {standard_task_runner.py:105} INFO - Job 250: Subtask store_to_sql_order_items
[2025-04-19T15:57:26.219+0000] {task_command.py:467} INFO - Running <TaskInstance: load_new_orders.store_to_sql_order_items scheduled__2025-04-19T14:00:00+00:00 [running]> on host 27536697ee14
[2025-04-19T15:57:26.436+0000] {taskinstance.py:3134} INFO - Exporting env vars: AIRFLOW_CTX_DAG_OWNER='azizjon' AIRFLOW_CTX_DAG_ID='load_new_orders' AIRFLOW_CTX_TASK_ID='store_to_sql_order_items' AIRFLOW_CTX_EXECUTION_DATE='2025-04-19T14:00:00+00:00' AIRFLOW_CTX_TRY_NUMBER='1' AIRFLOW_CTX_DAG_RUN_ID='scheduled__2025-04-19T14:00:00+00:00'
[2025-04-19T15:57:26.437+0000] {taskinstance.py:732} INFO - ::endgroup::
[2025-04-19T15:57:26.924+0000] {trigger_dagrun.py:257} INFO - Waiting for load_new_order_items on 2025-04-19 14:00:00+00:00 to become allowed state ['success'] ...
[2025-04-19T15:57:31.988+0000] {trigger_dagrun.py:257} INFO - Waiting for load_new_order_items on 2025-04-19 14:00:00+00:00 to become allowed state ['success'] ...
[2025-04-19T15:57:37.037+0000] {trigger_dagrun.py:257} INFO - Waiting for load_new_order_items on 2025-04-19 14:00:00+00:00 to become allowed state ['success'] ...
[2025-04-19T15:57:42.089+0000] {trigger_dagrun.py:257} INFO - Waiting for load_new_order_items on 2025-04-19 14:00:00+00:00 to become allowed state ['success'] ...
[2025-04-19T15:57:47.145+0000] {trigger_dagrun.py:257} INFO - Waiting for load_new_order_items on 2025-04-19 14:00:00+00:00 to become allowed state ['success'] ...
[2025-04-19T15:57:52.204+0000] {trigger_dagrun.py:257} INFO - Waiting for load_new_order_items on 2025-04-19 14:00:00+00:00 to become allowed state ['success'] ...
[2025-04-19T15:57:57.365+0000] {trigger_dagrun.py:257} INFO - Waiting for load_new_order_items on 2025-04-19 14:00:00+00:00 to become allowed state ['success'] ...
[2025-04-19T15:58:02.416+0000] {trigger_dagrun.py:257} INFO - Waiting for load_new_order_items on 2025-04-19 14:00:00+00:00 to become allowed state ['success'] ...
[2025-04-19T15:58:07.466+0000] {trigger_dagrun.py:257} INFO - Waiting for load_new_order_items on 2025-04-19 14:00:00+00:00 to become allowed state ['success'] ...
[2025-04-19T15:58:12.514+0000] {trigger_dagrun.py:257} INFO - Waiting for load_new_order_items on 2025-04-19 14:00:00+00:00 to become allowed state ['success'] ...
[2025-04-19T15:58:17.680+0000] {taskinstance.py:3313} ERROR - Task failed with exception
Traceback (most recent call last):
  File "/home/airflow/.local/lib/python3.12/site-packages/airflow/models/taskinstance.py", line 768, in _execute_task
    result = _execute_callable(context=context, **execute_callable_kwargs)
             ^^^^^^^^^^^^^^^^^^^^^^^^^^^^^^^^^^^^^^^^^^^^^^^^^^^^^^^^^^^^^
  File "/home/airflow/.local/lib/python3.12/site-packages/airflow/models/taskinstance.py", line 734, in _execute_callable
    return ExecutionCallableRunner(
           ^^^^^^^^^^^^^^^^^^^^^^^^
  File "/home/airflow/.local/lib/python3.12/site-packages/airflow/utils/operator_helpers.py", line 252, in run
    return self.func(*args, **kwargs)
           ^^^^^^^^^^^^^^^^^^^^^^^^^^
  File "/home/airflow/.local/lib/python3.12/site-packages/airflow/models/baseoperator.py", line 424, in wrapper
    return func(self, *args, **kwargs)
           ^^^^^^^^^^^^^^^^^^^^^^^^^^^
  File "/home/airflow/.local/lib/python3.12/site-packages/airflow/operators/trigger_dagrun.py", line 266, in execute
    dag_run.refresh_from_db()
  File "/home/airflow/.local/lib/python3.12/site-packages/airflow/utils/session.py", line 97, in wrapper
    return func(*args, session=session, **kwargs)
           ^^^^^^^^^^^^^^^^^^^^^^^^^^^^^^^^^^^^^^
  File "/home/airflow/.local/lib/python3.12/site-packages/airflow/models/dagrun.py", line 361, in refresh_from_db
    ).one()
      ^^^^^
  File "/home/airflow/.local/lib/python3.12/site-packages/sqlalchemy/engine/result.py", line 1522, in one
    return self._only_one_row(
           ^^^^^^^^^^^^^^^^^^^
  File "/home/airflow/.local/lib/python3.12/site-packages/sqlalchemy/engine/result.py", line 562, in _only_one_row
    raise exc.NoResultFound(
sqlalchemy.exc.NoResultFound: No row was found when one was required
[2025-04-19T15:58:17.734+0000] {taskinstance.py:1226} INFO - Marking task as FAILED. dag_id=load_new_orders, task_id=store_to_sql_order_items, run_id=scheduled__2025-04-19T14:00:00+00:00, execution_date=20250419T140000, start_date=20250419T155726, end_date=20250419T155817
[2025-04-19T15:58:17.743+0000] {taskinstance.py:341} INFO - ::group::Post task execution logs
[2025-04-19T15:58:17.744+0000] {standard_task_runner.py:124} ERROR - Failed to execute job 250 for task store_to_sql_order_items ((psycopg2.errors.ForeignKeyViolation) insert or update on table "task_fail" violates foreign key constraint "task_fail_ti_fkey"
DETAIL:  Key (dag_id, task_id, run_id, map_index)=(load_new_orders, store_to_sql_order_items, scheduled__2025-04-19T14:00:00+00:00, -1) is not present in table "task_instance".

[SQL: INSERT INTO task_fail (task_id, dag_id, run_id, map_index, start_date, end_date, duration) VALUES (%(task_id)s, %(dag_id)s, %(run_id)s, %(map_index)s, %(start_date)s, %(end_date)s, %(duration)s) RETURNING task_fail.id]
[parameters: {'task_id': 'store_to_sql_order_items', 'dag_id': 'load_new_orders', 'run_id': 'scheduled__2025-04-19T14:00:00+00:00', 'map_index': -1, 'start_date': datetime.datetime(2025, 4, 19, 15, 57, 26, 268, tzinfo=Timezone('UTC')), 'end_date': datetime.datetime(2025, 4, 19, 15, 58, 17, 734002, tzinfo=Timezone('UTC')), 'duration': 51}]
(Background on this error at: https://sqlalche.me/e/14/gkpj); 5556)
Traceback (most recent call last):
  File "/home/airflow/.local/lib/python3.12/site-packages/airflow/models/taskinstance.py", line 274, in _run_raw_task
    TaskInstance._execute_task_with_callbacks(
  File "/home/airflow/.local/lib/python3.12/site-packages/airflow/models/taskinstance.py", line 3161, in _execute_task_with_callbacks
    result = self._execute_task(context, task_orig)
             ^^^^^^^^^^^^^^^^^^^^^^^^^^^^^^^^^^^^^^
  File "/home/airflow/.local/lib/python3.12/site-packages/airflow/models/taskinstance.py", line 3185, in _execute_task
    return _execute_task(self, context, task_orig)
           ^^^^^^^^^^^^^^^^^^^^^^^^^^^^^^^^^^^^^^^
  File "/home/airflow/.local/lib/python3.12/site-packages/airflow/models/taskinstance.py", line 768, in _execute_task
    result = _execute_callable(context=context, **execute_callable_kwargs)
             ^^^^^^^^^^^^^^^^^^^^^^^^^^^^^^^^^^^^^^^^^^^^^^^^^^^^^^^^^^^^^
  File "/home/airflow/.local/lib/python3.12/site-packages/airflow/models/taskinstance.py", line 734, in _execute_callable
    return ExecutionCallableRunner(
           ^^^^^^^^^^^^^^^^^^^^^^^^
  File "/home/airflow/.local/lib/python3.12/site-packages/airflow/utils/operator_helpers.py", line 252, in run
    return self.func(*args, **kwargs)
           ^^^^^^^^^^^^^^^^^^^^^^^^^^
  File "/home/airflow/.local/lib/python3.12/site-packages/airflow/models/baseoperator.py", line 424, in wrapper
    return func(self, *args, **kwargs)
           ^^^^^^^^^^^^^^^^^^^^^^^^^^^
  File "/home/airflow/.local/lib/python3.12/site-packages/airflow/operators/trigger_dagrun.py", line 266, in execute
    dag_run.refresh_from_db()
  File "/home/airflow/.local/lib/python3.12/site-packages/airflow/utils/session.py", line 97, in wrapper
    return func(*args, session=session, **kwargs)
           ^^^^^^^^^^^^^^^^^^^^^^^^^^^^^^^^^^^^^^
  File "/home/airflow/.local/lib/python3.12/site-packages/airflow/models/dagrun.py", line 361, in refresh_from_db
    ).one()
      ^^^^^
  File "/home/airflow/.local/lib/python3.12/site-packages/sqlalchemy/engine/result.py", line 1522, in one
    return self._only_one_row(
           ^^^^^^^^^^^^^^^^^^^
  File "/home/airflow/.local/lib/python3.12/site-packages/sqlalchemy/engine/result.py", line 562, in _only_one_row
    raise exc.NoResultFound(
sqlalchemy.exc.NoResultFound: No row was found when one was required

During handling of the above exception, another exception occurred:

Traceback (most recent call last):
  File "/home/airflow/.local/lib/python3.12/site-packages/sqlalchemy/engine/base.py", line 1910, in _execute_context
    self.dialect.do_execute(
  File "/home/airflow/.local/lib/python3.12/site-packages/sqlalchemy/engine/default.py", line 736, in do_execute
    cursor.execute(statement, parameters)
psycopg2.errors.ForeignKeyViolation: insert or update on table "task_fail" violates foreign key constraint "task_fail_ti_fkey"
DETAIL:  Key (dag_id, task_id, run_id, map_index)=(load_new_orders, store_to_sql_order_items, scheduled__2025-04-19T14:00:00+00:00, -1) is not present in table "task_instance".


The above exception was the direct cause of the following exception:

Traceback (most recent call last):
  File "/home/airflow/.local/lib/python3.12/site-packages/airflow/task/task_runner/standard_task_runner.py", line 117, in _start_by_fork
    ret = args.func(args, dag=self.dag)
          ^^^^^^^^^^^^^^^^^^^^^^^^^^^^^
  File "/home/airflow/.local/lib/python3.12/site-packages/airflow/cli/cli_config.py", line 49, in command
    return func(*args, **kwargs)
           ^^^^^^^^^^^^^^^^^^^^^
  File "/home/airflow/.local/lib/python3.12/site-packages/airflow/utils/cli.py", line 116, in wrapper
    return f(*args, **kwargs)
           ^^^^^^^^^^^^^^^^^^
  File "/home/airflow/.local/lib/python3.12/site-packages/airflow/cli/commands/task_command.py", line 483, in task_run
    task_return_code = _run_task_by_selected_method(args, _dag, ti)
                       ^^^^^^^^^^^^^^^^^^^^^^^^^^^^^^^^^^^^^^^^^^^^
  File "/home/airflow/.local/lib/python3.12/site-packages/airflow/cli/commands/task_command.py", line 256, in _run_task_by_selected_method
    return _run_raw_task(args, ti)
           ^^^^^^^^^^^^^^^^^^^^^^^
  File "/home/airflow/.local/lib/python3.12/site-packages/airflow/cli/commands/task_command.py", line 341, in _run_raw_task
    return ti._run_raw_task(
           ^^^^^^^^^^^^^^^^^
  File "/home/airflow/.local/lib/python3.12/site-packages/airflow/utils/session.py", line 97, in wrapper
    return func(*args, session=session, **kwargs)
           ^^^^^^^^^^^^^^^^^^^^^^^^^^^^^^^^^^^^^^
  File "/home/airflow/.local/lib/python3.12/site-packages/airflow/models/taskinstance.py", line 3006, in _run_raw_task
    return _run_raw_task(
           ^^^^^^^^^^^^^^
  File "/home/airflow/.local/lib/python3.12/site-packages/airflow/models/taskinstance.py", line 337, in _run_raw_task
    ti.handle_failure(e, test_mode, context, session=session)
  File "/home/airflow/.local/lib/python3.12/site-packages/airflow/utils/session.py", line 94, in wrapper
    return func(*args, **kwargs)
           ^^^^^^^^^^^^^^^^^^^^^
  File "/home/airflow/.local/lib/python3.12/site-packages/airflow/models/taskinstance.py", line 3434, in handle_failure
    _handle_failure(
  File "/home/airflow/.local/lib/python3.12/site-packages/airflow/utils/session.py", line 94, in wrapper
    return func(*args, **kwargs)
           ^^^^^^^^^^^^^^^^^^^^^
  File "/home/airflow/.local/lib/python3.12/site-packages/airflow/api_internal/internal_api_call.py", line 166, in wrapper
    return func(*args, **kwargs)
           ^^^^^^^^^^^^^^^^^^^^^
  File "/home/airflow/.local/lib/python3.12/site-packages/airflow/models/taskinstance.py", line 1244, in _handle_failure
    TaskInstance.save_to_db(task_instance, session)
  File "/home/airflow/.local/lib/python3.12/site-packages/airflow/api_internal/internal_api_call.py", line 166, in wrapper
    return func(*args, **kwargs)
           ^^^^^^^^^^^^^^^^^^^^^
  File "/home/airflow/.local/lib/python3.12/site-packages/airflow/utils/session.py", line 94, in wrapper
    return func(*args, **kwargs)
           ^^^^^^^^^^^^^^^^^^^^^
  File "/home/airflow/.local/lib/python3.12/site-packages/airflow/models/taskinstance.py", line 3402, in save_to_db
    ti.get_dagrun().refresh_from_db()
    ^^^^^^^^^^^^^^^
  File "/home/airflow/.local/lib/python3.12/site-packages/airflow/utils/session.py", line 96, in wrapper
    with create_session() as session:
         ^^^^^^^^^^^^^^^^
  File "/usr/local/lib/python3.12/contextlib.py", line 144, in __exit__
    next(self.gen)
  File "/home/airflow/.local/lib/python3.12/site-packages/airflow/utils/session.py", line 57, in create_session
    session.commit()
  File "/home/airflow/.local/lib/python3.12/site-packages/sqlalchemy/orm/session.py", line 1454, in commit
    self._transaction.commit(_to_root=self.future)
  File "/home/airflow/.local/lib/python3.12/site-packages/sqlalchemy/orm/session.py", line 832, in commit
    self._prepare_impl()
  File "/home/airflow/.local/lib/python3.12/site-packages/sqlalchemy/orm/session.py", line 811, in _prepare_impl
    self.session.flush()
  File "/home/airflow/.local/lib/python3.12/site-packages/sqlalchemy/orm/session.py", line 3449, in flush
    self._flush(objects)
  File "/home/airflow/.local/lib/python3.12/site-packages/sqlalchemy/orm/session.py", line 3588, in _flush
    with util.safe_reraise():
         ^^^^^^^^^^^^^^^^^^^
  File "/home/airflow/.local/lib/python3.12/site-packages/sqlalchemy/util/langhelpers.py", line 70, in __exit__
    compat.raise_(
  File "/home/airflow/.local/lib/python3.12/site-packages/sqlalchemy/util/compat.py", line 211, in raise_
    raise exception
  File "/home/airflow/.local/lib/python3.12/site-packages/sqlalchemy/orm/session.py", line 3549, in _flush
    flush_context.execute()
  File "/home/airflow/.local/lib/python3.12/site-packages/sqlalchemy/orm/unitofwork.py", line 456, in execute
    rec.execute(self)
  File "/home/airflow/.local/lib/python3.12/site-packages/sqlalchemy/orm/unitofwork.py", line 630, in execute
    util.preloaded.orm_persistence.save_obj(
  File "/home/airflow/.local/lib/python3.12/site-packages/sqlalchemy/orm/persistence.py", line 245, in save_obj
    _emit_insert_statements(
  File "/home/airflow/.local/lib/python3.12/site-packages/sqlalchemy/orm/persistence.py", line 1238, in _emit_insert_statements
    result = connection._execute_20(
             ^^^^^^^^^^^^^^^^^^^^^^^
  File "/home/airflow/.local/lib/python3.12/site-packages/sqlalchemy/engine/base.py", line 1710, in _execute_20
    return meth(self, args_10style, kwargs_10style, execution_options)
           ^^^^^^^^^^^^^^^^^^^^^^^^^^^^^^^^^^^^^^^^^^^^^^^^^^^^^^^^^^^
  File "/home/airflow/.local/lib/python3.12/site-packages/sqlalchemy/sql/elements.py", line 334, in _execute_on_connection
    return connection._execute_clauseelement(
           ^^^^^^^^^^^^^^^^^^^^^^^^^^^^^^^^^^
  File "/home/airflow/.local/lib/python3.12/site-packages/sqlalchemy/engine/base.py", line 1577, in _execute_clauseelement
    ret = self._execute_context(
          ^^^^^^^^^^^^^^^^^^^^^^
  File "/home/airflow/.local/lib/python3.12/site-packages/sqlalchemy/engine/base.py", line 1953, in _execute_context
    self._handle_dbapi_exception(
  File "/home/airflow/.local/lib/python3.12/site-packages/sqlalchemy/engine/base.py", line 2134, in _handle_dbapi_exception
    util.raise_(
  File "/home/airflow/.local/lib/python3.12/site-packages/sqlalchemy/util/compat.py", line 211, in raise_
    raise exception
  File "/home/airflow/.local/lib/python3.12/site-packages/sqlalchemy/engine/base.py", line 1910, in _execute_context
    self.dialect.do_execute(
  File "/home/airflow/.local/lib/python3.12/site-packages/sqlalchemy/engine/default.py", line 736, in do_execute
    cursor.execute(statement, parameters)
sqlalchemy.exc.IntegrityError: (psycopg2.errors.ForeignKeyViolation) insert or update on table "task_fail" violates foreign key constraint "task_fail_ti_fkey"
DETAIL:  Key (dag_id, task_id, run_id, map_index)=(load_new_orders, store_to_sql_order_items, scheduled__2025-04-19T14:00:00+00:00, -1) is not present in table "task_instance".

[SQL: INSERT INTO task_fail (task_id, dag_id, run_id, map_index, start_date, end_date, duration) VALUES (%(task_id)s, %(dag_id)s, %(run_id)s, %(map_index)s, %(start_date)s, %(end_date)s, %(duration)s) RETURNING task_fail.id]
[parameters: {'task_id': 'store_to_sql_order_items', 'dag_id': 'load_new_orders', 'run_id': 'scheduled__2025-04-19T14:00:00+00:00', 'map_index': -1, 'start_date': datetime.datetime(2025, 4, 19, 15, 57, 26, 268, tzinfo=Timezone('UTC')), 'end_date': datetime.datetime(2025, 4, 19, 15, 58, 17, 734002, tzinfo=Timezone('UTC')), 'duration': 51}]
(Background on this error at: https://sqlalche.me/e/14/gkpj)
[2025-04-19T15:58:17.757+0000] {local_task_job_runner.py:266} INFO - Task exited with return code 1
[2025-04-19T15:58:17.811+0000] {local_task_job_runner.py:245} INFO - ::endgroup::
