[2025-04-18T11:16:20.724+0000] {local_task_job_runner.py:123} INFO - ::group::Pre task execution logs
[2025-04-18T11:16:20.788+0000] {taskinstance.py:2614} INFO - Dependencies all met for dep_context=non-requeueable deps ti=<TaskInstance: dbt_etl_pipeline_test.dbt_test manual__2025-04-18T11:12:53.480094+00:00 [queued]>
[2025-04-18T11:16:20.801+0000] {taskinstance.py:2614} INFO - Dependencies all met for dep_context=requeueable deps ti=<TaskInstance: dbt_etl_pipeline_test.dbt_test manual__2025-04-18T11:12:53.480094+00:00 [queued]>
[2025-04-18T11:16:20.803+0000] {taskinstance.py:2867} INFO - Starting attempt 2 of 2
[2025-04-18T11:16:20.824+0000] {taskinstance.py:2890} INFO - Executing <Task(BashOperator): dbt_test> on 2025-04-18 11:12:53.480094+00:00
[2025-04-18T11:16:20.832+0000] {standard_task_runner.py:104} INFO - Running: ['airflow', 'tasks', 'run', 'dbt_etl_pipeline_test', 'dbt_test', 'manual__2025-04-18T11:12:53.480094+00:00', '--job-id', '87', '--raw', '--subdir', 'DAGS_FOLDER/dbt_test.py', '--cfg-path', '/tmp/tmp5fbw0r5z']
[2025-04-18T11:16:20.834+0000] {standard_task_runner.py:105} INFO - Job 87: Subtask dbt_test
[2025-04-18T11:16:20.834+0000] {logging_mixin.py:190} WARNING - /home/airflow/.local/lib/python3.12/site-packages/airflow/task/task_runner/standard_task_runner.py:70 DeprecationWarning: This process (pid=662) is multi-threaded, use of fork() may lead to deadlocks in the child.
[2025-04-18T11:16:20.835+0000] {standard_task_runner.py:72} INFO - Started process 663 to run task
[2025-04-18T11:16:21.014+0000] {task_command.py:467} INFO - Running <TaskInstance: dbt_etl_pipeline_test.dbt_test manual__2025-04-18T11:12:53.480094+00:00 [running]> on host f693ba064550
[2025-04-18T11:16:21.233+0000] {taskinstance.py:3134} INFO - Exporting env vars: AIRFLOW_CTX_DAG_OWNER='azizjon' AIRFLOW_CTX_DAG_ID='dbt_etl_pipeline_test' AIRFLOW_CTX_TASK_ID='dbt_test' AIRFLOW_CTX_EXECUTION_DATE='2025-04-18T11:12:53.480094+00:00' AIRFLOW_CTX_TRY_NUMBER='2' AIRFLOW_CTX_DAG_RUN_ID='manual__2025-04-18T11:12:53.480094+00:00'
[2025-04-18T11:16:21.234+0000] {taskinstance.py:732} INFO - ::endgroup::
[2025-04-18T11:16:21.246+0000] {subprocess.py:78} INFO - Tmp dir root location: /tmp
[2025-04-18T11:16:21.249+0000] {subprocess.py:88} INFO - Running command: ['/usr/bin/bash', '-c', '\n        export PATH=/home/airflow/.local/bin:$PATH\n        cd /opt/airflow/commerce_dbt\n        dbt test --profiles-dir .\n        ']
[2025-04-18T11:16:21.258+0000] {subprocess.py:99} INFO - Output:
[2025-04-18T11:16:23.505+0000] {subprocess.py:106} INFO - [0m11:16:23  Running with dbt=1.7.0
[2025-04-18T11:16:23.779+0000] {subprocess.py:106} INFO - [0m11:16:23  Registered adapter: postgres=1.7.0
[2025-04-18T11:16:23.822+0000] {subprocess.py:106} INFO - [0m11:16:23  Unable to do partial parsing because of a version mismatch
[2025-04-18T11:16:25.644+0000] {subprocess.py:106} INFO - [0m11:16:25  [[33mWARNING[0m]: Configuration paths exist in your dbt_project.yml file which do not apply to any resources.
[2025-04-18T11:16:25.644+0000] {subprocess.py:106} INFO - There are 1 unused configuration paths:
[2025-04-18T11:16:25.645+0000] {subprocess.py:106} INFO - - seeds.initial_dataset
[2025-04-18T11:16:25.689+0000] {subprocess.py:106} INFO - [0m11:16:25  Found 12 models, 1 snapshot, 6 seeds, 43 tests, 6 sources, 0 exposures, 0 metrics, 401 macros, 0 groups, 0 semantic models
[2025-04-18T11:16:25.694+0000] {subprocess.py:106} INFO - [0m11:16:25
[2025-04-18T11:16:25.750+0000] {subprocess.py:106} INFO - [0m11:16:25
[2025-04-18T11:16:25.751+0000] {subprocess.py:106} INFO - [0m11:16:25  Finished running  in 0 hours 0 minutes and 0.06 seconds (0.06s).
[2025-04-18T11:16:25.751+0000] {subprocess.py:106} INFO - [0m11:16:25  Encountered an error:
[2025-04-18T11:16:25.751+0000] {subprocess.py:106} INFO - Database Error
[2025-04-18T11:16:25.752+0000] {subprocess.py:106} INFO -   connection to server at "localhost" (::1), port 5432 failed: Connection refused
[2025-04-18T11:16:25.752+0000] {subprocess.py:106} INFO -   	Is the server running on that host and accepting TCP/IP connections?
[2025-04-18T11:16:25.753+0000] {subprocess.py:106} INFO -   connection to server at "localhost" (127.0.0.1), port 5432 failed: Connection refused
[2025-04-18T11:16:25.753+0000] {subprocess.py:106} INFO -   	Is the server running on that host and accepting TCP/IP connections?
[2025-04-18T11:16:25.754+0000] {subprocess.py:106} INFO - 
[2025-04-18T11:16:26.718+0000] {subprocess.py:110} INFO - Command exited with return code 2
[2025-04-18T11:16:26.776+0000] {taskinstance.py:3313} ERROR - Task failed with exception
Traceback (most recent call last):
  File "/home/airflow/.local/lib/python3.12/site-packages/airflow/models/taskinstance.py", line 768, in _execute_task
    result = _execute_callable(context=context, **execute_callable_kwargs)
             ^^^^^^^^^^^^^^^^^^^^^^^^^^^^^^^^^^^^^^^^^^^^^^^^^^^^^^^^^^^^^
  File "/home/airflow/.local/lib/python3.12/site-packages/airflow/models/taskinstance.py", line 734, in _execute_callable
    return ExecutionCallableRunner(
           ^^^^^^^^^^^^^^^^^^^^^^^^
  File "/home/airflow/.local/lib/python3.12/site-packages/airflow/utils/operator_helpers.py", line 252, in run
    return self.func(*args, **kwargs)
           ^^^^^^^^^^^^^^^^^^^^^^^^^^
  File "/home/airflow/.local/lib/python3.12/site-packages/airflow/models/baseoperator.py", line 424, in wrapper
    return func(self, *args, **kwargs)
           ^^^^^^^^^^^^^^^^^^^^^^^^^^^
  File "/home/airflow/.local/lib/python3.12/site-packages/airflow/operators/bash.py", line 276, in execute
    raise AirflowException(
airflow.exceptions.AirflowException: Bash command failed. The command returned a non-zero exit code 2.
[2025-04-18T11:16:26.781+0000] {taskinstance.py:1226} INFO - Marking task as FAILED. dag_id=dbt_etl_pipeline_test, task_id=dbt_test, run_id=manual__2025-04-18T11:12:53.480094+00:00, execution_date=20250418T111253, start_date=20250418T111620, end_date=20250418T111626
[2025-04-18T11:16:26.905+0000] {taskinstance.py:341} INFO - ::group::Post task execution logs
[2025-04-18T11:16:26.906+0000] {standard_task_runner.py:124} ERROR - Failed to execute job 87 for task dbt_test (Bash command failed. The command returned a non-zero exit code 2.; 663)
Traceback (most recent call last):
  File "/home/airflow/.local/lib/python3.12/site-packages/airflow/task/task_runner/standard_task_runner.py", line 117, in _start_by_fork
    ret = args.func(args, dag=self.dag)
          ^^^^^^^^^^^^^^^^^^^^^^^^^^^^^
  File "/home/airflow/.local/lib/python3.12/site-packages/airflow/cli/cli_config.py", line 49, in command
    return func(*args, **kwargs)
           ^^^^^^^^^^^^^^^^^^^^^
  File "/home/airflow/.local/lib/python3.12/site-packages/airflow/utils/cli.py", line 116, in wrapper
    return f(*args, **kwargs)
           ^^^^^^^^^^^^^^^^^^
  File "/home/airflow/.local/lib/python3.12/site-packages/airflow/cli/commands/task_command.py", line 483, in task_run
    task_return_code = _run_task_by_selected_method(args, _dag, ti)
                       ^^^^^^^^^^^^^^^^^^^^^^^^^^^^^^^^^^^^^^^^^^^^
  File "/home/airflow/.local/lib/python3.12/site-packages/airflow/cli/commands/task_command.py", line 256, in _run_task_by_selected_method
    return _run_raw_task(args, ti)
           ^^^^^^^^^^^^^^^^^^^^^^^
  File "/home/airflow/.local/lib/python3.12/site-packages/airflow/cli/commands/task_command.py", line 341, in _run_raw_task
    return ti._run_raw_task(
           ^^^^^^^^^^^^^^^^^
  File "/home/airflow/.local/lib/python3.12/site-packages/airflow/utils/session.py", line 97, in wrapper
    return func(*args, session=session, **kwargs)
           ^^^^^^^^^^^^^^^^^^^^^^^^^^^^^^^^^^^^^^
  File "/home/airflow/.local/lib/python3.12/site-packages/airflow/models/taskinstance.py", line 3006, in _run_raw_task
    return _run_raw_task(
           ^^^^^^^^^^^^^^
  File "/home/airflow/.local/lib/python3.12/site-packages/airflow/models/taskinstance.py", line 274, in _run_raw_task
    TaskInstance._execute_task_with_callbacks(
  File "/home/airflow/.local/lib/python3.12/site-packages/airflow/models/taskinstance.py", line 3161, in _execute_task_with_callbacks
    result = self._execute_task(context, task_orig)
             ^^^^^^^^^^^^^^^^^^^^^^^^^^^^^^^^^^^^^^
  File "/home/airflow/.local/lib/python3.12/site-packages/airflow/models/taskinstance.py", line 3185, in _execute_task
    return _execute_task(self, context, task_orig)
           ^^^^^^^^^^^^^^^^^^^^^^^^^^^^^^^^^^^^^^^
  File "/home/airflow/.local/lib/python3.12/site-packages/airflow/models/taskinstance.py", line 768, in _execute_task
    result = _execute_callable(context=context, **execute_callable_kwargs)
             ^^^^^^^^^^^^^^^^^^^^^^^^^^^^^^^^^^^^^^^^^^^^^^^^^^^^^^^^^^^^^
  File "/home/airflow/.local/lib/python3.12/site-packages/airflow/models/taskinstance.py", line 734, in _execute_callable
    return ExecutionCallableRunner(
           ^^^^^^^^^^^^^^^^^^^^^^^^
  File "/home/airflow/.local/lib/python3.12/site-packages/airflow/utils/operator_helpers.py", line 252, in run
    return self.func(*args, **kwargs)
           ^^^^^^^^^^^^^^^^^^^^^^^^^^
  File "/home/airflow/.local/lib/python3.12/site-packages/airflow/models/baseoperator.py", line 424, in wrapper
    return func(self, *args, **kwargs)
           ^^^^^^^^^^^^^^^^^^^^^^^^^^^
  File "/home/airflow/.local/lib/python3.12/site-packages/airflow/operators/bash.py", line 276, in execute
    raise AirflowException(
airflow.exceptions.AirflowException: Bash command failed. The command returned a non-zero exit code 2.
[2025-04-18T11:16:26.914+0000] {local_task_job_runner.py:266} INFO - Task exited with return code 1
[2025-04-18T11:16:26.971+0000] {taskinstance.py:3901} INFO - 0 downstream tasks scheduled from follow-on schedule check
[2025-04-18T11:16:26.974+0000] {local_task_job_runner.py:245} INFO - ::endgroup::
