[2025-04-17T20:03:27.749+0000] {local_task_job_runner.py:123} INFO - ::group::Pre task execution logs
[2025-04-17T20:03:27.811+0000] {taskinstance.py:2614} INFO - Dependencies all met for dep_context=non-requeueable deps ti=<TaskInstance: dbt_etl_pipeline.dbt_seed manual__2025-04-17T20:03:26.879484+00:00 [queued]>
[2025-04-17T20:03:27.823+0000] {taskinstance.py:2614} INFO - Dependencies all met for dep_context=requeueable deps ti=<TaskInstance: dbt_etl_pipeline.dbt_seed manual__2025-04-17T20:03:26.879484+00:00 [queued]>
[2025-04-17T20:03:27.824+0000] {taskinstance.py:2867} INFO - Starting attempt 1 of 2
[2025-04-17T20:03:27.841+0000] {taskinstance.py:2890} INFO - Executing <Task(BashOperator): dbt_seed> on 2025-04-17 20:03:26.879484+00:00
[2025-04-17T20:03:27.849+0000] {standard_task_runner.py:104} INFO - Running: ['airflow', 'tasks', 'run', 'dbt_etl_pipeline', 'dbt_seed', 'manual__2025-04-17T20:03:26.879484+00:00', '--job-id', '6', '--raw', '--subdir', 'DAGS_FOLDER/trigger_dbt.py', '--cfg-path', '/tmp/tmpg5o0knqz']
[2025-04-17T20:03:27.852+0000] {logging_mixin.py:190} WARNING - /home/airflow/.local/lib/python3.12/site-packages/airflow/task/task_runner/standard_task_runner.py:70 DeprecationWarning: This process (pid=205) is multi-threaded, use of fork() may lead to deadlocks in the child.
[2025-04-17T20:03:27.853+0000] {standard_task_runner.py:105} INFO - Job 6: Subtask dbt_seed
[2025-04-17T20:03:27.853+0000] {standard_task_runner.py:72} INFO - Started process 206 to run task
[2025-04-17T20:03:28.060+0000] {task_command.py:467} INFO - Running <TaskInstance: dbt_etl_pipeline.dbt_seed manual__2025-04-17T20:03:26.879484+00:00 [running]> on host df781dd46ffb
[2025-04-17T20:03:28.409+0000] {taskinstance.py:3134} INFO - Exporting env vars: AIRFLOW_CTX_DAG_OWNER='azizjon' AIRFLOW_CTX_DAG_ID='dbt_etl_pipeline' AIRFLOW_CTX_TASK_ID='dbt_seed' AIRFLOW_CTX_EXECUTION_DATE='2025-04-17T20:03:26.879484+00:00' AIRFLOW_CTX_TRY_NUMBER='1' AIRFLOW_CTX_DAG_RUN_ID='manual__2025-04-17T20:03:26.879484+00:00'
[2025-04-17T20:03:28.410+0000] {taskinstance.py:732} INFO - ::endgroup::
[2025-04-17T20:03:28.443+0000] {subprocess.py:78} INFO - Tmp dir root location: /tmp
[2025-04-17T20:03:28.445+0000] {subprocess.py:88} INFO - Running command: ['/usr/bin/bash', '-c', 'cd /opt/airflow/dbt_project && dbt seed --profiles-dir .']
[2025-04-17T20:03:28.454+0000] {subprocess.py:99} INFO - Output:
[2025-04-17T20:03:28.455+0000] {subprocess.py:106} INFO - /usr/bin/bash: line 1: cd: /opt/airflow/dbt_project: No such file or directory
[2025-04-17T20:03:28.456+0000] {subprocess.py:110} INFO - Command exited with return code 1
[2025-04-17T20:03:28.523+0000] {taskinstance.py:3313} ERROR - Task failed with exception
Traceback (most recent call last):
  File "/home/airflow/.local/lib/python3.12/site-packages/airflow/models/taskinstance.py", line 768, in _execute_task
    result = _execute_callable(context=context, **execute_callable_kwargs)
             ^^^^^^^^^^^^^^^^^^^^^^^^^^^^^^^^^^^^^^^^^^^^^^^^^^^^^^^^^^^^^
  File "/home/airflow/.local/lib/python3.12/site-packages/airflow/models/taskinstance.py", line 734, in _execute_callable
    return ExecutionCallableRunner(
           ^^^^^^^^^^^^^^^^^^^^^^^^
  File "/home/airflow/.local/lib/python3.12/site-packages/airflow/utils/operator_helpers.py", line 252, in run
    return self.func(*args, **kwargs)
           ^^^^^^^^^^^^^^^^^^^^^^^^^^
  File "/home/airflow/.local/lib/python3.12/site-packages/airflow/models/baseoperator.py", line 424, in wrapper
    return func(self, *args, **kwargs)
           ^^^^^^^^^^^^^^^^^^^^^^^^^^^
  File "/home/airflow/.local/lib/python3.12/site-packages/airflow/operators/bash.py", line 276, in execute
    raise AirflowException(
airflow.exceptions.AirflowException: Bash command failed. The command returned a non-zero exit code 1.
[2025-04-17T20:03:28.532+0000] {taskinstance.py:1226} INFO - Marking task as UP_FOR_RETRY. dag_id=dbt_etl_pipeline, task_id=dbt_seed, run_id=manual__2025-04-17T20:03:26.879484+00:00, execution_date=20250417T200326, start_date=20250417T200327, end_date=20250417T200328
[2025-04-17T20:03:28.666+0000] {taskinstance.py:341} INFO - ::group::Post task execution logs
[2025-04-17T20:03:28.667+0000] {standard_task_runner.py:124} ERROR - Failed to execute job 6 for task dbt_seed (Bash command failed. The command returned a non-zero exit code 1.; 206)
Traceback (most recent call last):
  File "/home/airflow/.local/lib/python3.12/site-packages/airflow/task/task_runner/standard_task_runner.py", line 117, in _start_by_fork
    ret = args.func(args, dag=self.dag)
          ^^^^^^^^^^^^^^^^^^^^^^^^^^^^^
  File "/home/airflow/.local/lib/python3.12/site-packages/airflow/cli/cli_config.py", line 49, in command
    return func(*args, **kwargs)
           ^^^^^^^^^^^^^^^^^^^^^
  File "/home/airflow/.local/lib/python3.12/site-packages/airflow/utils/cli.py", line 116, in wrapper
    return f(*args, **kwargs)
           ^^^^^^^^^^^^^^^^^^
  File "/home/airflow/.local/lib/python3.12/site-packages/airflow/cli/commands/task_command.py", line 483, in task_run
    task_return_code = _run_task_by_selected_method(args, _dag, ti)
                       ^^^^^^^^^^^^^^^^^^^^^^^^^^^^^^^^^^^^^^^^^^^^
  File "/home/airflow/.local/lib/python3.12/site-packages/airflow/cli/commands/task_command.py", line 256, in _run_task_by_selected_method
    return _run_raw_task(args, ti)
           ^^^^^^^^^^^^^^^^^^^^^^^
  File "/home/airflow/.local/lib/python3.12/site-packages/airflow/cli/commands/task_command.py", line 341, in _run_raw_task
    return ti._run_raw_task(
           ^^^^^^^^^^^^^^^^^
  File "/home/airflow/.local/lib/python3.12/site-packages/airflow/utils/session.py", line 97, in wrapper
    return func(*args, session=session, **kwargs)
           ^^^^^^^^^^^^^^^^^^^^^^^^^^^^^^^^^^^^^^
  File "/home/airflow/.local/lib/python3.12/site-packages/airflow/models/taskinstance.py", line 3006, in _run_raw_task
    return _run_raw_task(
           ^^^^^^^^^^^^^^
  File "/home/airflow/.local/lib/python3.12/site-packages/airflow/models/taskinstance.py", line 274, in _run_raw_task
    TaskInstance._execute_task_with_callbacks(
  File "/home/airflow/.local/lib/python3.12/site-packages/airflow/models/taskinstance.py", line 3161, in _execute_task_with_callbacks
    result = self._execute_task(context, task_orig)
             ^^^^^^^^^^^^^^^^^^^^^^^^^^^^^^^^^^^^^^
  File "/home/airflow/.local/lib/python3.12/site-packages/airflow/models/taskinstance.py", line 3185, in _execute_task
    return _execute_task(self, context, task_orig)
           ^^^^^^^^^^^^^^^^^^^^^^^^^^^^^^^^^^^^^^^
  File "/home/airflow/.local/lib/python3.12/site-packages/airflow/models/taskinstance.py", line 768, in _execute_task
    result = _execute_callable(context=context, **execute_callable_kwargs)
             ^^^^^^^^^^^^^^^^^^^^^^^^^^^^^^^^^^^^^^^^^^^^^^^^^^^^^^^^^^^^^
  File "/home/airflow/.local/lib/python3.12/site-packages/airflow/models/taskinstance.py", line 734, in _execute_callable
    return ExecutionCallableRunner(
           ^^^^^^^^^^^^^^^^^^^^^^^^
  File "/home/airflow/.local/lib/python3.12/site-packages/airflow/utils/operator_helpers.py", line 252, in run
    return self.func(*args, **kwargs)
           ^^^^^^^^^^^^^^^^^^^^^^^^^^
  File "/home/airflow/.local/lib/python3.12/site-packages/airflow/models/baseoperator.py", line 424, in wrapper
    return func(self, *args, **kwargs)
           ^^^^^^^^^^^^^^^^^^^^^^^^^^^
  File "/home/airflow/.local/lib/python3.12/site-packages/airflow/operators/bash.py", line 276, in execute
    raise AirflowException(
airflow.exceptions.AirflowException: Bash command failed. The command returned a non-zero exit code 1.
[2025-04-17T20:03:28.712+0000] {local_task_job_runner.py:266} INFO - Task exited with return code 1
[2025-04-17T20:03:28.782+0000] {taskinstance.py:3901} INFO - 0 downstream tasks scheduled from follow-on schedule check
[2025-04-17T20:03:28.785+0000] {local_task_job_runner.py:245} INFO - ::endgroup::
