[2025-04-19T12:02:37.061+0000] {local_task_job_runner.py:123} INFO - ::group::Pre task execution logs
[2025-04-19T12:02:37.317+0000] {taskinstance.py:2614} INFO - Dependencies all met for dep_context=non-requeueable deps ti=<TaskInstance: dbt_etl_pipeline_staging.dbt_staging manual__2025-04-18T11:26:30.183256+00:00 [queued]>
[2025-04-19T12:02:37.354+0000] {taskinstance.py:2614} INFO - Dependencies all met for dep_context=requeueable deps ti=<TaskInstance: dbt_etl_pipeline_staging.dbt_staging manual__2025-04-18T11:26:30.183256+00:00 [queued]>
[2025-04-19T12:02:37.356+0000] {taskinstance.py:2867} INFO - Starting attempt 2 of 2
[2025-04-19T12:02:37.427+0000] {taskinstance.py:2890} INFO - Executing <Task(BashOperator): dbt_staging> on 2025-04-18 11:26:30.183256+00:00
[2025-04-19T12:02:37.470+0000] {logging_mixin.py:190} WARNING - /home/airflow/.local/lib/python3.12/site-packages/airflow/task/task_runner/standard_task_runner.py:70 DeprecationWarning: This process (pid=407) is multi-threaded, use of fork() may lead to deadlocks in the child.
[2025-04-19T12:02:37.475+0000] {standard_task_runner.py:72} INFO - Started process 427 to run task
[2025-04-19T12:02:37.466+0000] {standard_task_runner.py:104} INFO - Running: ['airflow', 'tasks', 'run', 'dbt_etl_pipeline_staging', 'dbt_staging', 'manual__2025-04-18T11:26:30.183256+00:00', '--job-id', '158', '--raw', '--subdir', 'DAGS_FOLDER/dbt_staging.py', '--cfg-path', '/tmp/tmp1df494ve']
[2025-04-19T12:02:37.485+0000] {standard_task_runner.py:105} INFO - Job 158: Subtask dbt_staging
[2025-04-19T12:02:38.405+0000] {task_command.py:467} INFO - Running <TaskInstance: dbt_etl_pipeline_staging.dbt_staging manual__2025-04-18T11:26:30.183256+00:00 [running]> on host 8310323359f9
[2025-04-19T12:02:39.398+0000] {taskinstance.py:3134} INFO - Exporting env vars: AIRFLOW_CTX_DAG_OWNER='azizjon' AIRFLOW_CTX_DAG_ID='dbt_etl_pipeline_staging' AIRFLOW_CTX_TASK_ID='dbt_staging' AIRFLOW_CTX_EXECUTION_DATE='2025-04-18T11:26:30.183256+00:00' AIRFLOW_CTX_TRY_NUMBER='2' AIRFLOW_CTX_DAG_RUN_ID='manual__2025-04-18T11:26:30.183256+00:00'
[2025-04-19T12:02:39.400+0000] {taskinstance.py:732} INFO - ::endgroup::
[2025-04-19T12:02:39.483+0000] {subprocess.py:78} INFO - Tmp dir root location: /tmp
[2025-04-19T12:02:39.502+0000] {subprocess.py:88} INFO - Running command: ['/usr/bin/bash', '-c', '\n        export PATH=/home/airflow/.local/bin:$PATH\n        cd /opt/airflow/commerce_dbt\n        dbt run --select staging --profiles-dir .\n        ']
[2025-04-19T12:02:39.558+0000] {subprocess.py:99} INFO - Output:
[2025-04-19T12:02:49.713+0000] {subprocess.py:106} INFO - [0m12:02:49  Running with dbt=1.7.0
[2025-04-19T12:02:51.039+0000] {subprocess.py:106} INFO - [0m12:02:51  Registered adapter: postgres=1.7.0
[2025-04-19T12:02:52.576+0000] {subprocess.py:106} INFO - [0m12:02:52  [[33mWARNING[0m]: Configuration paths exist in your dbt_project.yml file which do not apply to any resources.
[2025-04-19T12:02:52.578+0000] {subprocess.py:106} INFO - There are 1 unused configuration paths:
[2025-04-19T12:02:52.582+0000] {subprocess.py:106} INFO - - seeds.initial_dataset
[2025-04-19T12:02:52.951+0000] {subprocess.py:106} INFO - [0m12:02:52  Found 13 models, 1 snapshot, 6 seeds, 43 tests, 6 sources, 0 exposures, 0 metrics, 401 macros, 0 groups, 0 semantic models
[2025-04-19T12:02:52.967+0000] {subprocess.py:106} INFO - [0m12:02:52
[2025-04-19T12:02:55.784+0000] {subprocess.py:106} INFO - [0m12:02:55  Concurrency: 4 threads (target='dev')
[2025-04-19T12:02:55.809+0000] {subprocess.py:106} INFO - [0m12:02:55
[2025-04-19T12:02:56.263+0000] {subprocess.py:106} INFO - [0m12:02:56  1 of 6 START sql table model commerce_staging.stg_customers .................... [RUN]
[2025-04-19T12:02:56.284+0000] {subprocess.py:106} INFO - [0m12:02:56  2 of 6 START sql table model commerce_staging.stg_order_items .................. [RUN]
[2025-04-19T12:02:56.301+0000] {subprocess.py:106} INFO - [0m12:02:56  3 of 6 START sql table model commerce_staging.stg_orders ....................... [RUN]
[2025-04-19T12:02:56.305+0000] {subprocess.py:106} INFO - [0m12:02:56  4 of 6 START sql table model commerce_staging.stg_product_categories ........... [RUN]
[2025-04-19T12:02:57.788+0000] {subprocess.py:106} INFO - [0m12:02:57  1 of 6 ERROR creating sql table model commerce_staging.stg_customers ........... [[31mERROR[0m in 1.46s]
[2025-04-19T12:02:57.832+0000] {subprocess.py:106} INFO - [0m12:02:57  2 of 6 ERROR creating sql table model commerce_staging.stg_order_items ......... [[31mERROR[0m in 1.51s]
[2025-04-19T12:02:57.896+0000] {subprocess.py:106} INFO - [0m12:02:57  5 of 6 START sql table model commerce_staging.stg_products ..................... [RUN]
[2025-04-19T12:02:57.919+0000] {subprocess.py:106} INFO - [0m12:02:57  4 of 6 ERROR creating sql table model commerce_staging.stg_product_categories .. [[31mERROR[0m in 1.59s]
[2025-04-19T12:02:57.921+0000] {subprocess.py:106} INFO - [0m12:02:57  6 of 6 START sql table model commerce_staging.stg_stores ....................... [RUN]
[2025-04-19T12:02:58.045+0000] {subprocess.py:106} INFO - [0m12:02:58  3 of 6 ERROR creating sql table model commerce_staging.stg_orders .............. [[31mERROR[0m in 1.72s]
[2025-04-19T12:02:58.302+0000] {subprocess.py:106} INFO - [0m12:02:58  5 of 6 ERROR creating sql table model commerce_staging.stg_products ............ [[31mERROR[0m in 0.39s]
[2025-04-19T12:02:58.305+0000] {subprocess.py:106} INFO - [0m12:02:58  6 of 6 ERROR creating sql table model commerce_staging.stg_stores .............. [[31mERROR[0m in 0.36s]
[2025-04-19T12:02:58.403+0000] {subprocess.py:106} INFO - [0m12:02:58
[2025-04-19T12:02:58.404+0000] {subprocess.py:106} INFO - [0m12:02:58  Finished running 6 table models in 0 hours 0 minutes and 5.41 seconds (5.41s).
[2025-04-19T12:02:58.446+0000] {subprocess.py:106} INFO - [0m12:02:58
[2025-04-19T12:02:58.447+0000] {subprocess.py:106} INFO - [0m12:02:58  [31mCompleted with 6 errors and 0 warnings:[0m
[2025-04-19T12:02:58.448+0000] {subprocess.py:106} INFO - [0m12:02:58
[2025-04-19T12:02:58.449+0000] {subprocess.py:106} INFO - [0m12:02:58    Database Error in model stg_customers (models/staging/stg_customers.sql)
[2025-04-19T12:02:58.449+0000] {subprocess.py:106} INFO -   relation "stg_customers" already exists
[2025-04-19T12:02:58.450+0000] {subprocess.py:106} INFO -   compiled Code at target/run/commerce_dbt/models/staging/stg_customers.sql
[2025-04-19T12:02:58.450+0000] {subprocess.py:106} INFO - [0m12:02:58
[2025-04-19T12:02:58.451+0000] {subprocess.py:106} INFO - [0m12:02:58    Database Error in model stg_order_items (models/staging/stg_order_items.sql)
[2025-04-19T12:02:58.452+0000] {subprocess.py:106} INFO -   relation "stg_order_items" already exists
[2025-04-19T12:02:58.453+0000] {subprocess.py:106} INFO -   compiled Code at target/run/commerce_dbt/models/staging/stg_order_items.sql
[2025-04-19T12:02:58.454+0000] {subprocess.py:106} INFO - [0m12:02:58
[2025-04-19T12:02:58.454+0000] {subprocess.py:106} INFO - [0m12:02:58    Database Error in model stg_product_categories (models/staging/stg_product_categories.sql)
[2025-04-19T12:02:58.458+0000] {subprocess.py:106} INFO -   relation "stg_product_categories" already exists
[2025-04-19T12:02:58.459+0000] {subprocess.py:106} INFO -   compiled Code at target/run/commerce_dbt/models/staging/stg_product_categories.sql
[2025-04-19T12:02:58.460+0000] {subprocess.py:106} INFO - [0m12:02:58
[2025-04-19T12:02:58.462+0000] {subprocess.py:106} INFO - [0m12:02:58    Database Error in model stg_orders (models/staging/stg_orders.sql)
[2025-04-19T12:02:58.463+0000] {subprocess.py:106} INFO -   relation "stg_orders" already exists
[2025-04-19T12:02:58.463+0000] {subprocess.py:106} INFO -   compiled Code at target/run/commerce_dbt/models/staging/stg_orders.sql
[2025-04-19T12:02:58.464+0000] {subprocess.py:106} INFO - [0m12:02:58
[2025-04-19T12:02:58.465+0000] {subprocess.py:106} INFO - [0m12:02:58    Database Error in model stg_products (models/staging/stg_products.sql)
[2025-04-19T12:02:58.466+0000] {subprocess.py:106} INFO -   relation "stg_products" already exists
[2025-04-19T12:02:58.466+0000] {subprocess.py:106} INFO -   compiled Code at target/run/commerce_dbt/models/staging/stg_products.sql
[2025-04-19T12:02:58.467+0000] {subprocess.py:106} INFO - [0m12:02:58
[2025-04-19T12:02:58.467+0000] {subprocess.py:106} INFO - [0m12:02:58    Database Error in model stg_stores (models/staging/stg_stores.sql)
[2025-04-19T12:02:58.467+0000] {subprocess.py:106} INFO -   relation "stg_stores" already exists
[2025-04-19T12:02:58.468+0000] {subprocess.py:106} INFO -   compiled Code at target/run/commerce_dbt/models/staging/stg_stores.sql
[2025-04-19T12:02:58.469+0000] {subprocess.py:106} INFO - [0m12:02:58
[2025-04-19T12:02:58.470+0000] {subprocess.py:106} INFO - [0m12:02:58  Done. PASS=0 WARN=0 ERROR=6 SKIP=0 TOTAL=6
[2025-04-19T12:03:01.147+0000] {subprocess.py:110} INFO - Command exited with return code 1
[2025-04-19T12:03:01.409+0000] {taskinstance.py:3313} ERROR - Task failed with exception
Traceback (most recent call last):
  File "/home/airflow/.local/lib/python3.12/site-packages/airflow/models/taskinstance.py", line 768, in _execute_task
    result = _execute_callable(context=context, **execute_callable_kwargs)
             ^^^^^^^^^^^^^^^^^^^^^^^^^^^^^^^^^^^^^^^^^^^^^^^^^^^^^^^^^^^^^
  File "/home/airflow/.local/lib/python3.12/site-packages/airflow/models/taskinstance.py", line 734, in _execute_callable
    return ExecutionCallableRunner(
           ^^^^^^^^^^^^^^^^^^^^^^^^
  File "/home/airflow/.local/lib/python3.12/site-packages/airflow/utils/operator_helpers.py", line 252, in run
    return self.func(*args, **kwargs)
           ^^^^^^^^^^^^^^^^^^^^^^^^^^
  File "/home/airflow/.local/lib/python3.12/site-packages/airflow/models/baseoperator.py", line 424, in wrapper
    return func(self, *args, **kwargs)
           ^^^^^^^^^^^^^^^^^^^^^^^^^^^
  File "/home/airflow/.local/lib/python3.12/site-packages/airflow/operators/bash.py", line 276, in execute
    raise AirflowException(
airflow.exceptions.AirflowException: Bash command failed. The command returned a non-zero exit code 1.
[2025-04-19T12:03:01.431+0000] {taskinstance.py:1226} INFO - Marking task as UP_FOR_RETRY. dag_id=dbt_etl_pipeline_staging, task_id=dbt_staging, run_id=manual__2025-04-18T11:26:30.183256+00:00, execution_date=20250418T112630, start_date=20250419T120237, end_date=20250419T120301
[2025-04-19T12:03:02.119+0000] {taskinstance.py:341} INFO - ::group::Post task execution logs
[2025-04-19T12:03:02.156+0000] {standard_task_runner.py:124} ERROR - Failed to execute job 158 for task dbt_staging (Bash command failed. The command returned a non-zero exit code 1.; 427)
Traceback (most recent call last):
  File "/home/airflow/.local/lib/python3.12/site-packages/airflow/task/task_runner/standard_task_runner.py", line 117, in _start_by_fork
    ret = args.func(args, dag=self.dag)
          ^^^^^^^^^^^^^^^^^^^^^^^^^^^^^
  File "/home/airflow/.local/lib/python3.12/site-packages/airflow/cli/cli_config.py", line 49, in command
    return func(*args, **kwargs)
           ^^^^^^^^^^^^^^^^^^^^^
  File "/home/airflow/.local/lib/python3.12/site-packages/airflow/utils/cli.py", line 116, in wrapper
    return f(*args, **kwargs)
           ^^^^^^^^^^^^^^^^^^
  File "/home/airflow/.local/lib/python3.12/site-packages/airflow/cli/commands/task_command.py", line 483, in task_run
    task_return_code = _run_task_by_selected_method(args, _dag, ti)
                       ^^^^^^^^^^^^^^^^^^^^^^^^^^^^^^^^^^^^^^^^^^^^
  File "/home/airflow/.local/lib/python3.12/site-packages/airflow/cli/commands/task_command.py", line 256, in _run_task_by_selected_method
    return _run_raw_task(args, ti)
           ^^^^^^^^^^^^^^^^^^^^^^^
  File "/home/airflow/.local/lib/python3.12/site-packages/airflow/cli/commands/task_command.py", line 341, in _run_raw_task
    return ti._run_raw_task(
           ^^^^^^^^^^^^^^^^^
  File "/home/airflow/.local/lib/python3.12/site-packages/airflow/utils/session.py", line 97, in wrapper
    return func(*args, session=session, **kwargs)
           ^^^^^^^^^^^^^^^^^^^^^^^^^^^^^^^^^^^^^^
  File "/home/airflow/.local/lib/python3.12/site-packages/airflow/models/taskinstance.py", line 3006, in _run_raw_task
    return _run_raw_task(
           ^^^^^^^^^^^^^^
  File "/home/airflow/.local/lib/python3.12/site-packages/airflow/models/taskinstance.py", line 274, in _run_raw_task
    TaskInstance._execute_task_with_callbacks(
  File "/home/airflow/.local/lib/python3.12/site-packages/airflow/models/taskinstance.py", line 3161, in _execute_task_with_callbacks
    result = self._execute_task(context, task_orig)
             ^^^^^^^^^^^^^^^^^^^^^^^^^^^^^^^^^^^^^^
  File "/home/airflow/.local/lib/python3.12/site-packages/airflow/models/taskinstance.py", line 3185, in _execute_task
    return _execute_task(self, context, task_orig)
           ^^^^^^^^^^^^^^^^^^^^^^^^^^^^^^^^^^^^^^^
  File "/home/airflow/.local/lib/python3.12/site-packages/airflow/models/taskinstance.py", line 768, in _execute_task
    result = _execute_callable(context=context, **execute_callable_kwargs)
             ^^^^^^^^^^^^^^^^^^^^^^^^^^^^^^^^^^^^^^^^^^^^^^^^^^^^^^^^^^^^^
  File "/home/airflow/.local/lib/python3.12/site-packages/airflow/models/taskinstance.py", line 734, in _execute_callable
    return ExecutionCallableRunner(
           ^^^^^^^^^^^^^^^^^^^^^^^^
  File "/home/airflow/.local/lib/python3.12/site-packages/airflow/utils/operator_helpers.py", line 252, in run
    return self.func(*args, **kwargs)
           ^^^^^^^^^^^^^^^^^^^^^^^^^^
  File "/home/airflow/.local/lib/python3.12/site-packages/airflow/models/baseoperator.py", line 424, in wrapper
    return func(self, *args, **kwargs)
           ^^^^^^^^^^^^^^^^^^^^^^^^^^^
  File "/home/airflow/.local/lib/python3.12/site-packages/airflow/operators/bash.py", line 276, in execute
    raise AirflowException(
airflow.exceptions.AirflowException: Bash command failed. The command returned a non-zero exit code 1.
[2025-04-19T12:03:02.221+0000] {local_task_job_runner.py:266} INFO - Task exited with return code 1
[2025-04-19T12:03:02.484+0000] {standard_task_runner.py:217} INFO - Process not found (most likely exited), stop collecting metrics
[2025-04-19T12:03:02.549+0000] {local_task_job_runner.py:245} INFO - ::endgroup::
